Workbook

Sheet 목차
B2: [목 차] | D2: [자료 추출 기준]
B4: 1. 2023년 용도별 건축물 현황 | D4: [1] 자료기준일 : 2023.12.31
B5: 2. 2023년 주거용 건축물 현황 | D5: [2] 추출 대상 대장 : 건축물대장
B6: 3. 2023년 상업용 건축물 현황 | D6: [3] 추출 기준
B7: 4. 2023년 고층 건축물 현황 | D7: 1. 주/부 구분 : 주건축물 (부속건축물 제외)
B8: 5. 2023년 경과년수별 건축물 현황 | D8: 2. 사용승인일 : ~ 2023.12.31
B9: 6. 2023년 말소 건축물 용도별 현황 | D9: 2.1 (말소건축물) 말소일 : 2023.1.1 ~ 2023.12.31
B10: 7. 2023년 층수, 면적, 소유주체별 현황 | D10: 3. 용도 : 층별 용도
B11: 8. 2023년 1인당 건축물 현황 | D11: 4. 동수 : 층별 대표 용도를 추출하여 동별 용도로 산정
B12: 9. 2023년 국토면적 대비 건축물 현황 | D12: 5. 연면적 : (용도별) 층 면적의 합

Sheet 1. 용도별
A1: =목차!B4 -> 1. 2023년 용도별 건축물 현황
N2: (단위 : 동, ㎡)
B3: 시도 | C3: 합계 | E3: 주거용 | G3: 상업용 | I3: 공업용 | K3: 교육 및 사회용 | M3: 기타
C4: 동수 | D4: 연면적 | E4: 동수 | F4: 연면적 | G4: 동수 | H4: 연면적 | I4: 동수 | J4: 연면적 | K4: 동수 | L4: 연면적 | M4: 동수 | N4: 연면적
B5: 전국 | C5: 7391084 | D5: 4.2276607e+09 | E5: 4576735 | F5: 1.9505563e+09 | G5: 1392582 | H5: 9.3468869e+08 | I5: 345087 | J5: 4.6514802e+08 | K5: 203489 | L5: 3.7664541e+08 | M5: 873191 | N5: 5.0062229e+08
B6: 서울특별시 | C6: 579408 | D6: 5.9422332e+08 | E6: 428325 | F6: 3.0847809e+08 | G6: 127876 | H6: 1.8678264e+08 | I6: 2322 | J6: 14552067 | K6: 16367 | L6: 63430315 | M6: 4518 | N6: 20980204
B7: 부산광역시 | C7: 348634 | D7: 2.5584108e+08 | E7: 236696 | F7: 1.2462408e+08 | G7: 73754 | H7: 64595346 | I7: 15784 | J7: 19867250 | K7: 9260 | L7: 23981385 | M7: 13140 | N7: 22773015
B8: 대구광역시 | C8: 256241 | D8: 1.8144026e+08 | E8: 168976 | F8: 95283309 | G8: 54117 | H8: 45453596 | I8: 13375 | J8: 16290192 | K8: 6637 | L8: 16051156 | M8: 13136 | N8: 8362007.8
B9: 인천광역시 | C9: 221783 | D9: 2.2303799e+08 | E9: 138739 | F9: 1.0741546e+08 | G9: 47743 | H9: 55915629 | I9: 14723 | J9: 25115386 | K9: 6664 | L9: 18087502 | M9: 13914 | N9: 16504017
B10: 광주광역시 | C10: 136197 | D10: 1.1011157e+08 | E10: 89137 | F10: 59857078 | G10: 33625 | H10: 24411788 | I10: 4404 | J10: 8781783.8 | K10: 4056 | L10: 12869132 | M10: 4975 | N10: 4191793.4
B11: 대전광역시 | C11: 131054 | D11: 1.1635192e+08 | E11: 90228 | F11: 57280772 | G11: 27220 | H11: 25161964 | I11: 3028 | J11: 5662874.7 | K11: 5043 | L11: 15094653 | M11: 5535 | N11: 13151653
B12: 울산광역시 | C12: 137107 | D12: 94810829 | E12: 76205 | F12: 44358548 | G12: 31203 | H12: 18547143 | I12: 15113 | J12: 18653920 | K12: 4023 | L12: 7335576.7 | M12: 10563 | N12: 5915641.6
B13: 세종특별자치시 | C13: 35383 | D13: 31939700 | E13: 19428 | F13: 16035868 | G13: 6833 | H13: 5875166.6 | I13: 2064 | J13: 2982271.5 | K13: 1040 | L13: 3300221.3 | M13: 6018 | N13: 3746172.5
B14: 경기도 | C14: 1265969 | D14: 1.1085574e+09 | E14: 659642 | F14: 5.0265909e+08 | G14: 296848 | H14: 2.2877838e+08 | I14: 114900 | J14: 1.3591984e+08 | K14: 37213 | L14: 84771583 | M14: 157366 | N14: 1.5642847e+08
B15: 강원특별자치도 | C15: 437539 | D15: 1.4583537e+08 | E15: 278327 | F15: 64847506 | G15: 79287 | H15: 33239229 | I15: 7559 | J15: 7464148.8 | K15: 14249 | L15: 17151380 | M15: 58117 | N15: 23133107
B16: 충청북도 | C16: 407286 | D16: 1.6200215e+08 | E16: 247945 | F16: 68352953 | G16: 66614 | H16: 27674039 | I16: 22051 | J16: 29701761 | K16: 11143 | L16: 13844344 | M16: 59533 | N16: 22429053
... B22: 제주특별자치도 | C22: 189336 | D22: 59414426 | E22: 114852 | F22: 25424250 | G22: 32688 | H22: 19920379 | I22: 1025 | J22: 849633.85 | K22: 4332 | L22: 5540625.6 | M22: 36439 | N22: 7679537.4

Sheet 2. 주거용
A1: =목차!B5 -> 2. 2023년 주거용 건축물 현황
A2: [기준] 기타 : 주거용(주용도) 기준 면적에서 상세용도 합 제외
V3: (단위 : 동, ㎡)
B4: 시도 | C4: 합계 | E4: 단독주택 | G4: 다중주택 | I4: 다가구주택 | K4: 공관 | M4: 아파트 | O4: 연립주택 | Q4: 다세대 | S4: 기숙사 | U4: 기타
C5: 동수 | D5: 연면적 | E5: 동수 | F5: 연면적 | G5: 동수 | H5: 연면적 | I5: 동수 | J5: 연면적 | K5: 동수 | L5: 연면적 | M5: 동수 | N5: 연면적 | O5: 동수 | P5: 연면적 | Q5: 동수 | R5: 연면적 | S5: 동수 | T5: 연면적 | U5: 동수 | V5: 연면적
B6: 전국 | C6: 4576735 | D6: 1.9505563e+09 | E6: 3496849 | F6: 3.3280967e+08 | G6: 20008 | H6: 5775055.9 | I6: 590452 | J6: 1.7216179e+08 | K6: 1538 | L6: 366016.61 | M6: 164724 | N6: 1.2524653e+09 | O6: 36564 | P6: 44880428 | Q6: 258060 | R6: 1.3353604e+08 | S6: 3865 | T6: 7708354.9 | U6: 4675 | V6: 853595.83
B7: 서울특별시 | C7: 428325 | D7: 3.0847809e+08 | E7: 180336 | F7: 26402312 | G7: 9623 | H7: 2818705.9 | I7: 110205 | J7: 28338972 | K7: 45 | L7: 44390.24 | M7: 25506 | N7: 1.937418e+08 | O7: 8707 | P7: 10049709 | Q7: 93627 | R7: 46385895 | S7: 268 | T7: 692457.02 | U7: 8 | V7: 3850.72
B8: 부산광역시 | C8: 236696 | D8: 1.2462408e+08 | E8: 170603 | F8: 14956218 | G8: 401 | H8: 110019.88 | I8: 33560 | J8: 6101516.1 | K8: 40 | L8: 6871.71 | M8: 11330 | N8: 92317223 | O8: 2203 | P8: 2038888.8 | Q8: 18462 | R8: 8900687.6 | S8: 65 | T8: 156227.88 | U8: 32 | V8: 36429.013
B9: 대구광역시 | C9: 168976 | D9: 95283309 | E9: 103166 | F9: 11241349 | G9: 653 | H9: 178771.47 | I9: 48686 | J9: 12593618 | K9: 15 | L9: 5585.61 | M9: 7982 | N9: 66448819 | O9: 487 | P9: 651146.01 | Q9: 7221 | R9: 3747030.7 | S9: 82 | T9: 287799.29 | U9: 684 | V9: 129190.25
B10: 인천광역시 | C10: 138739 | D10: 1.0741546e+08 | E10: 78332 | F10: 8559122 | G10: 760 | H10: 227914.69 | I10: 22271 | J10: 6240306.9 | K10: 127 | L10: 25021.07 | M10: 9535 | N10: 77367295 | O10: 1857 | P10: 2339556.8 | Q10: 25287 | R10: 12392575 | S10: 64 | T10: 176346.42 | U10: 506 | V10: 87321.683
B11: 광주광역시 | C11: 89137 | D11: 59857078 | E11: 66190 | F11: 7518752.1 | G11: 138 | H11: 37405.23 | I11: 15545 | J11: 5118988.5 | K11: 0 | L11: 278.43 | M11: 5590 | N11: 45547191 | O11: 820 | P11: 1072261.4 | Q11: 797 | R11: 408270.92 | S11: 38 | T11: 142476.48 | U11: 19 | V11: 11454.259
B12: 대전광역시 | C12: 90228 | D12: 57280772 | E12: 47248 | F12: 5101521.3 | G12: 3011 | H12: 899893.46 | I12: 30421 | J12: 8929781.7 | K12: 8 | L12: 7087.57 | M12: 4424 | N12: 39130227 | O12: 783 | P12: 910761.4 | Q12: 4257 | R12: 2101769.6 | S12: 75 | T12: 197238.07 | U12: 1 | V12: 2492.11
B13: 울산광역시 | C13: 76205 | D13: 44358548 | E13: 52161 | F13: 6429616.9 | G13: 197 | H13: 56127.848 | I13: 16227 | J13: 5128396.8 | K13: 45 | L13: 8004.21 | M13: 4185 | N13: 30270009 | O13: 540 | P13: 570832.92 | Q13: 2674 | R13: 1535986.9 | S13: 125 | T13: 353544.77 | U13: 51 | V13: 6028.425
B14: 세종특별자치시 | C14: 19428 | D14: 16035868 | E14: 15783 | F14: 1580340.7 | G14: 139 | H14: 41947.15 | I14: 1265 | J14: 557840.2 | K14: 9 | L14: 1126.84 | M14: 1956 | N14: 13632923 | O14: 70 | P14: 89054.706 | Q14: 187 | R14: 89346.868 | S14: 19 | T14: 43288.625 | U14: 0 | V14: 0
B15: 경기도 | C15: 659642 | D15: 5.0265909e+08 | E15: 392071 | F15: 47811176 | G15: 1360 | H15: 393972.59 | I15: 135533 | J15: 40655431 | K15: 165 | L15: 64380.409 | M15: 43314 | N15: 3.5701926e+08 | O15: 8393 | P15: 11932874 | Q15: 77737 | R15: 42991945 | S15: 941 | T15: 1629295.9 | U15: 128 | V15: 160753.51
B16: 강원특별자치도 | C16: 278327 | D16: 64847506 | E16: 243530 | F16: 21127879 | G16: 296 | H16: 78329.038 | I16: 25340 | J16: 6934930.3 | K16: 221 | L16: 38191.376 | M16: 5257 | N16: 33696420 | O16: 1602 | P16: 1610516.1 | Q16: 1727 | R16: 874689.52 | S16: 253 | T16: 458762.72 | U16: 101 | V16: 27788.833
B17: 충청북도 | C17: 247945 | D17: 68352953 | E17: 215465 | F17: 20193733 | G17: 713 | H17: 208462.31 | I17: 22078 | J17: 7883851.7 | K17: 36 | L17: 8411.8248 | M17: 5228 | N17: 36849675 | O17: 1107 | P17: 1196849.7 | Q17: 2557 | R17: 1561048.8 | S17: 167 | T17: 417015.16 | U17: 594 | V17: 33905.637
... B23: 제주특별자치도 | C23: 114852 | D23: 25424250 | E23: 94537 | F23: 9002315.8 | G23: 83 | H23: 18614.53 | I23: 10802 | J23: 3077074.8 | K23: 17 | L23: 7469.28 | M23: 2090 | N23: 7349083.1 | O23: 2215 | P23: 3119586.4 | Q23: 4993 | R23: 2676301.6 | S23: 101 | T23: 169723.57 | U23: 14 | V23: 4080.832

Sheet 3. 상업용
A1: =목차!B6 -> 3. 2023년 상업용 건축물 현황
A2: [기준] 기타 : 상업용(주용도) 기준 면적에서 상세용도 합 제외
X3: (단위 : 동, ㎡)
B4: 시도 | C4: 합계 | E4: 제1종근린생활시설 | G4: 제2종근린생활시설 | I4: 판매시설 | K4: 업무시설 | M4: 위락시설 | O4: 숙박시설 | Q4: 운수시설 | S4: 위험물저장 및 처리시설 | U4: 자동차관련시설 | W4: 기타
C5: 동수 | D5: 연면적 | E5: 동수 | F5: 연면적 | G5: 동수 | H5: 연면적 | I5: 동수 | J5: 연면적 | K5: 동수 | L5: 연면적 | M5: 동수 | N5: 연면적 | O5: 동수 | P5: 연면적 | Q5: 동수 | R5: 연면적 | S5: 동수 | T5: 연면적 | U5: 동수 | V5: 연면적 | W5: 동수 | X5: 연면적
B6: 전국 | C6: 1392582 | D6: 9.3468869e+08 | E6: 562479 | F6: 2.4561442e+08 | G6: 649454 | H6: 2.9588673e+08 | I6: 11742 | J6: 66337441 | K6: 31848 | L6: 1.8163271e+08 | M6: 6032 | N6: 6850859.1 | O6: 45250 | P6: 54995788 | Q6: 3916 | R6: 14707497 | S6: 32141 | T6: 6751492 | U6: 33440 | V6: 47175747 | W6: 16280 | X6: 14735998
B7: 서울특별시 | C7: 127876 | D7: 1.8678264e+08 | E7: 53487 | F7: 38847799 | G7: 56730 | H7: 44673506 | I7: 1199 | J7: 18422101 | K7: 9845 | L7: 65096795 | M7: 207 | N7: 524057.71 | O7: 1913 | P7: 6166146.6 | Q7: 261 | R7: 1523645.7 | S7: 650 | T7: 247420.44 | U7: 1712 | V7: 8065750 | W7: 1872 | X7: 3215418
B8: 부산광역시 | C8: 73754 | D8: 64595346 | E8: 27770 | F8: 14149779 | G8: 34667 | H8: 20591011 | I8: 936 | J8: 5201259.3 | K8: 3332 | L8: 13257037 | M8: 336 | N8: 630927.66 | O8: 2357 | P8: 4376449.2 | Q8: 432 | R8: 1775746.6 | S8: 1206 | T8: 225343.74 | U8: 1756 | V8: 3528263 | W8: 962 | X8: 859530.3
B9: 대구광역시 | C9: 54117 | D9: 45453596 | E9: 22628 | F9: 12699332 | G9: 25200 | H9: 13403514 | I9: 1079 | J9: 3028015.2 | K9: 963 | L9: 8652736.4 | M9: 224 | N9: 311205.16 | O9: 942 | P9: 1295444.4 | Q9: 157 | R9: 2898961.6 | S9: 873 | T9: 163786.23 | U9: 1337 | V9: 2106367.7 | W9: 714 | X9: 894232.55
B10: 인천광역시 | C10: 47743 | D10: 55915629 | E10: 17821 | F10: 11956109 | G10: 21368 | H10: 14391960 | I10: 514 | J10: 4172641.1 | K10: 1971 | L10: 13771872 | M10: 162 | N10: 275906.02 | O10: 1951 | P10: 2552771 | Q10: 662 | R10: 4783608.7 | S10: 1218 | T10: 382464.52 | U10: 1397 | V10: 2898847.2 | W10: 679 | X10: 729449.44
B11: 광주광역시 | C11: 33625 | D11: 24411788 | E11: 14183 | F11: 6770066.6 | G11: 15345 | H11: 8061995 | I11: 346 | J11: 1541448.4 | K11: 598 | L11: 3486290.6 | M11: 129 | N11: 216453.75 | O11: 881 | P11: 900395.26 | Q11: 75 | R11: 221792.2 | S11: 469 | T11: 100428.31 | U11: 962 | V11: 1365906.4 | W11: 637 | X11: 1747011.3
B12: 대전광역시 | C12: 27220 | D12: 25161964 | E12: 10184 | F12: 6933105.6 | G12: 13155 | H12: 8701625.9 | I12: 781 | J12: 2407837.5 | K12: 545 | L12: 3821031.9 | M12: 69 | N12: 138251.8 | O12: 776 | P12: 1132280.4 | Q12: 56 | R12: 101140.7 | S12: 580 | T12: 135255.62 | U12: 835 | V12: 1484067.9 | W12: 239 | X12: 307367.21
B13: 울산광역시 | C13: 31203 | D13: 18547143 | E13: 11506 | F13: 5366977.1 | G13: 14912 | H13: 6275319.1 | I13: 235 | J13: 1300578.8 | K13: 565 | L13: 2453687.9 | M13: 278 | N13: 242742.72 | O13: 789 | P13: 938892.08 | Q13: 87 | R13: 76188.36 | S13: 1481 | T13: 595227.56 | U13: 1024 | V13: 1134520.5 | W13: 326 | X13: 163008.65
B14: 세종특별자치시 | C14: 6833 | D14: 5875166.6 | E14: 2457 | F14: 1844712.4 | G14: 3622 | H14: 2054444.2 | I14: 31 | J14: 427318.11 | K14: 95 | L14: 1084721.7 | M14: 7 | N14: 8554.24 | O14: 98 | P14: 125856.3 | Q14: 14 | R14: 8610.32 | S14: 276 | T14: 72054.954 | U14: 171 | V14: 234582.4 | W14: 62 | X14: 14311.919
B15: 경기도 | C15: 296848 | D15: 2.2877838e+08 | E15: 102345 | F15: 57261256 | G15: 159910 | H15: 77634204 | I15: 1768 | J15: 17039995 | K15: 5637 | L15: 45631437 | M15: 644 | N15: 1059904.4 | O15: 7040 | P15: 7774843 | Q15: 550 | R15: 1563583.5 | S15: 6945 | T15: 1779238.9 | U15: 8406 | V15: 15587882 | W15: 3603 | X15: 3446041.4
B16: 강원특별자치도 | C16: 79287 | D16: 33239229 | E16: 31485 | F16: 8917862 | G16: 34845 | H16: 11079876 | I16: 479 | J16: 1257660 | K16: 917 | L16: 1924617.9 | M16: 477 | N16: 445537.85 | O16: 5748 | P16: 7371977.1 | Q16: 194 | R16: 161362.11 | S16: 1813 | T16: 302751.58 | U16: 1898 | V16: 1305526 | W16: 1431 | X16: 472058.9
B17: 충청북도 | C17: 66614 | D17: 27674039 | E17: 28303 | F17: 9565669 | G17: 30634 | H17: 10693002 | I17: 341 | J17: 1174864.4 | K17: 790 | L17: 1921100.3 | M17: 223 | N17: 261087.11 | O17: 1914 | P17: 1948053.6 | Q17: 96 | R17: 152653.37 | S17: 1897 | T17: 325249.03 | U17: 1786 | V17: 1288533 | W17: 630 | X17: 343826.82
... B23: 제주특별자치도 | C23: 32688 | D23: 19920379 | E23: 12437 | F23: 4301321.1 | G23: 14706 | H23: 5079793.6 | I23: 84 | J23: 273934.44 | K23: 389 | L23: 4026869.8 | M23: 211 | N23: 242272.43 | O23: 3551 | P23: 5028070.3 | Q23: 94 | R23: 223485.54 | S23: 594 | T23: 101007.69 | U23: 531 | V23: 586236.89 | W23: 91 | X23: 57387.238

Sheet 4. 고층
A1: =목차!B7 -> 4. 2023년 고층 건축물 현황
B3: □ 건축물 현황
B4: 순위 | C4: 구분 | D4: 건물명 | E4: 동명칭 | F4: 지상층수 | G4: 위치
B5: 1 | C5: 건축물대장 | D5: 롯데월드타워앤드롯데월드몰 | E5: 월드타워동 | F5: 123 | G5: 서울특별시 송파구 신천동 29번지
B6: 2 | C6: 건축물대장 | D6: 엘시티 | E6: 랜드마크타워동 | F6: 101 | G6: 부산광역시 해운대구 중동 1829번지
B7: 3 | C7: 건축물대장 | D7: 엘시티 | E7: 타워비동 | F7: 85 | G7: 부산광역시 해운대구 중동 1829번지
B8: 4 | C8: 건축물대장 | D8: 엘시티 | E8: 타워에이동 | F8: 85 | G8: 부산광역시 해운대구 중동 1829번지
B9: 5 | C9: 건축물대장 | D9: 해운대 두산위브더제니스 | E9: 101동 | F9: 80 | G9: 부산광역시 해운대구 우동 1407번지
B10: 6 | C10: 건축물대장 | D10: 해운대 두산위브더제니스 | E10: 102동 | F10: 75 | G10: 부산광역시 해운대구 우동 1407번지
B11: 7 | C11: 건축물대장 | D11: 해운대 l'PARK | E11: 주동2 | F11: 72 | G11: 부산광역시 해운대구 우동 1408번지
B12: 8 | C12: 건축물대장 | D12: 해운대 두산위브더제니스 | E12: 103동 | F12: 70 | G12: 부산광역시 해운대구 우동 1407번지
B13: 9 | C13: 건축물대장 | D13: 힐스테이트이진베이시티아파트 | E13: 공동주택A동 | F13: 69 | G13: 부산광역시 서구 암남동 123-15번지
B14: 10 | C14: 건축물대장 | D14: 파크원 | E14: 타워1 | F14: 69 | G14: 서울특별시 영등포구 여의도동 22번지
B15: 11 | C15: 건축물대장 | D15: 더블유 | E15: 비동 | F15: 69 | G15: 부산광역시 남구 용호동 954번지
B16: 12 | C16: 건축물대장 | D16: 더블유 | E16: 씨동 | F16: 69 | G16: 부산광역시 남구 용호동 954번지
... B19: 15 | C19: 건축물대장 | D19: 타워팰리스 | E19: 지동 | F19: 69 | G19: 서울특별시 강남구 도곡동 467-29번지
B20: 16 | C20: 건축물대장 | D20: 현대하이페리온 | F20: 69 | G20: 서울특별시 양천구 목동 916번지
B21: 17 | C21: 건축물대장 | E21: 포스코타워-송도 | F21: 68 | G21: 인천광역시 연수구 송도동 6-9번지
B22: 18 | C22: 건축물대장 | D22: 리첸시아 중동 | F22: 66 | G22: 경기도 부천시 중동 1116번지
B23: 19 | C23: 건축물대장 | D23: 펜타포트 | E23: 103동 | F23: 66 | G23: 충청남도 천안시 서북구 불당동 1289번지
B24: 20 | C24: 건축물대장 | D24: 해운대 l'PARK | E24: 주동1 | F24: 66 | G24: 부산광역시 해운대구 우동 1408번지
B26: □ 건설중인 건축물 현황
B27: 순위 | C27: 구분 | D27: 건물명 | E27: 동명칭 | F27: 지상층수 | G27: 위치
B28: 1 | C28: 건축 | D28: 현대자동차부지 특별계획구역 복합시설(GBC) 신축사업 | E28: 업무시설1 | F28: 105 | G28: 서울특별시 강남구 삼성동 167
B29: 2 | C29: 건축 | D29: 송악읍 고대리 당진1철강산업단지 C1블럭 공장 (현대제철 주식회사) | E29: 27동 전기실 및 운전실 | F29: 98 | G29: 충청남도 당진시 송악읍 당진1철강산업단지 C1블럭
B30: 3 | C30: 건축 | D30: 아산배방지구 11BL 생활숙박시설 개발사업 | E30: 생활숙박시설,판매시설 | F30: 70 | G30: 충청남도 아산시 배방읍 장재리 1733
B31: 4 | C31: 주택 | D31: 부산 동구 범일동 주거복합 | E31: 102동(아파트) | F31: 69 | G31: 부산광역시 동구 범일동 330-226
B32: 5 | C32: 주택 | D32: 부산 동구 범일동 주거복합 | E32: 102동(아파트) | F32: 69 | G32: 부산광역시 동구 범일동 330-226
B33: 6 | C33: 주택 | D33: 부산 동구 범일동 주거복합 | E33: 101동(아파트) | F33: 61 | G33: 부산광역시 동구 범일동 330-226
B34: 7 | C34: 주택 | D34: 부산 동구 범일동 주거복합 | E34: 101동(아파트) | F34: 61 | G34: 부산광역시 동구 범일동 330-226
B35: 8 | C35: 건축 | D35: 롯데캐슬 드메르 | E35: 주건축물제1동 | F35: 59 | G35: 부산광역시 동구 초량동 부산항(북항) 재개발사업지 내 상업업무지구 D-3블록
B36: 9 | C36: 건축 | D36: 서울시 영등포구 여의도동 23-4 복합시설 | E36: 주건축물제1동 | F36: 57 | G36: 서울특별시 영등포구 여의도동 23-4
B37: 10 | C37: 건축 | D37: 서울숲 e편한세상 | E37: 서울숲 e편한세상 | F37: 51 | G37: 서울특별시 성동구 성수동1가 685-700
B38: 11 | C38: 건축 | D38: 서울숲 e편한세상 | E38: 서울숲 e편한세상 | F38: 51 | G38: 서울특별시 성동구 성수동1가 685-700
B39: 12 | C39: 건축 | D39: 서울숲 e편한세상 | E39: 서울숲 e편한세상 | F39: 51 | G39: 서울특별시 성동구 성수동1가 685-700
B40: 13 | C40: 건축 | D40: DTV ST 블럭호텔 | E40: Edifice-WHITE(104) | F40: 50 | G40: 대전광역시 유성구 용산동 579
B42: □ 지역별 최고층 건축물
B43: 시도 | D43: 건물명 | E43: 동명칭 | F43: 지상층수 | G43: 위치
B44: 서울특별시 | D44: 롯데월드타워앤드롯데월드몰 | E44: 월드타워동 | F44: 123 | G44: 서울특별시 송파구 신천동 29
B45: 부산광역시 | D45: 중동 18290000 숙박시설 (주식회사엘시티피이에프브이) | E45: 랜드마크타워동 | F45: 101 | G45: 부산광역시 해운대구 중동 1829
...

Sheet 8. 고층건축물 BACKUP(건축물대장)
A1: MGM_BLDRGST_PK | B1: SIGUNGU_CD | C1: BLD_NM | D1: DONG_NM | E1: GRND_FLR_CNT | F1: F_PLAT_PLC_PRT(X01.SIGUNGU_CD,X01.BJDONG_CD,X01.PLAT_GB_CD,X01.BUN,X01.JI,X01.SPLOT_NM,X01.BLOCK,X01.LOT)
A2: 11680-2345 | B2: 11680 | C2: 타워팰리스 | D2: 지동 | E2: 69 | F2: 서울특별시 강남구 도곡동 467-29번지
A3: 11470-8842 | B3: 11470 | C3: 현대하이페리온 | E3: 69 | F3: 서울특별시 양천구 목동 916번지
A4: 11680-2201 | B4: 11680 | C4: 타워팰리스 | D4: 비동 | E4: 66 | F4: 서울특별시 강남구 도곡동 467번지
A5: 11560-100190515 | B5: 11560 | C5: 한화금융센터_63 | E5: 60 | F5: 서울특별시 영등포구 여의도동 60번지
A6: 11680-2200 | B6: 11680 | C6: 타워팰리스 | D6: 씨동 | E6: 59 | F6: 서울특별시 강남구 도곡동 467번지
A7: 11680-2202 | B7: 11680 | C7: 타워팰리스 | D7: 에이동 | E7: 59 | F7: 서울특별시 강남구 도곡동 467번지
A8: 11215-20199 | B8: 11215 | C8: 더샵스타시티 | D8: A동 | E8: 58 | F8: 서울특별시 광진구 자양동 227-7번지
A9: 11680-2210 | B9: 11680 | C9: 타워팰리스 | D9: 에프동 | E9: 55 | F9: 서울특별시 강남구 도곡동 467-17번지
A10: 11680-2211 | B10: 11680 | C10: 타워팰리스 | D10: 이동 | E10: 55 | F10: 서울특별시 강남구 도곡동 467-17번지
A11: 11680-22357 | B11: 11680 | C11: 무역회관 | E11: 54 | F11: 서울특별시 강남구 삼성동 159번지
A12: 11680-2508 | B12: 11680 | C12: 아카데미스위트 | D12: 에이동 | E12: 51 | F12: 서울특별시 강남구 도곡동 467-7번지
A13: 11530-100194390 | B13: 11530 | C13: 디큐브시티 | D13: 아파트동 | E13: 51 | F13: 서울특별시 구로구 신도림동 692번지
A14: 11215-20200 | B14: 11215 | C14: 더샵스타시티 | D14: C동 | E14: 50 | F14: 서울특별시 광진구 자양동 227-7번지
A15: 11215-100185549 | B15: 11215 | C15: 더 클래식500 | D15: 노유자시설동 | E15: 50 | F15: 서울특별시 광진구 자양동 227-342번지
A16: 11470-100184978 | B16: 11470 | C16: 목동트라팰리스 웨스턴에비뉴 | E16: 49 | F16: 서울특별시 양천구 목동 962번지
A17: 11590-25074 | B17: 11590 | C17: 보라매삼성쉐르빌 | E17: 49 | F17: 서울특별시 동작구 신대방동 395-66번지
A18: 11470-100184668 | B18: 11470 | C18: 목동트라팰리스 이스턴에비뉴 | E18: 48 | F18: 서울특별시 양천구 목동 962-1번지
A19: 11710-16738 | B19: 11710 | C19: 갤러리아팰리스 | E19: 46 | F19: 서울특별시 송파구 잠실동 40번지
A20: 11680-2339 | B20: 11680 | C20: 아이파크삼성동 | D20: 사우스윙 | E20: 46 | F20: 서울특별시 강남구 삼성동 87번지
A21: 11680-2341 | B21: 11680 | C21: 아이파크삼성동 | D21: 웨스트윙 | E21: 46 | F21: 서울특별시 강남구 삼성동 87번지
A22: 26350-100204451 | B22: 26350 | C22: 해운대 두산위브더제니스 | D22: 101동 | E22: 80 | F22: 부산광역시 해운대구 우동 1407번지
A23: 26350-100205080 | B23: 26350 | C23: 해운대 두산위브더제니스 | D23: 102동 | E23: 75 | F23: 부산광역시 해운대구 우동 1407번지
A24: 26350-100202586 | B24: 26350 | C24: 해운대 l'PARK | D24: 주동2 | E24: 72 | F24: 부산광역시 해운대구 우동 1408번지
A25: 26350-100205669 | B25: 26350 | C25: 해운대 두산위브더제니스 | D25: 103동 | E25: 70 | F25: 부산광역시 해운대구 우동 1407번지
A26: 26350-100203236 | B26: 26350 | C26: 해운대 l'PARK | D26: 주동1 | E26: 66 | F26: 부산광역시 해운대구 우동 1408번지
A27: 26350-100188472 | B27: 26350 | C27: the# 센텀스타 | D27: B동 | E27: 60 | F27: 부산광역시 해운대구 재송동 1196번지
A28: 26230-100188570 | B28: 26230 | C28: 더샵 센트럴스타 | D28: A동 | E28: 58 | F28: 부산광역시 부산진구 부전동 537-9번지
A29: 26350-100188968 | B29: 26350 | C29: the# 센텀스타 | D29: C동 | E29: 52 | F29: 부산광역시 해운대구 재송동 1196번지
A30: 26260-100172067 | B30: 26260 | C30: 벽산아스타 | D30: 101동 | E30: 52 | F30: 부산광역시 동래구 온천동 178-7번지
A31: 26350-16595 | B31: 26350 | C31: 더샵 센텀파크 1차 아파트 | D31: 104동 | E31: 51 | F31: 부산광역시 해운대구 재송동 1200번지
... A41: 26350-16596 | B41: 26350 | C41: 더샵 센텀파크 1차 아파트 | D41: 106동 | E41: 51 | F41: 부산광역시 해운대구 재송동 1200번지
A42: 27260-100198919 | B42: 27260 | C42: 수성 SK 리더스뷰 | D42: 103 | E42: 57 | F42: 대구광역시 수성구 두산동 113번지
A43: 27260-100199331 | B43: 27260 | C43: 수성 SK 리더스뷰 | D43: 105 | E43: 57 | F43: 대구광역시 수성구 두산동 113번지
A44: 27260-100194897 | B44: 27260 | C44: 두산위브더제니스 | D44: 106동 | E44: 54 | F44: 대구광역시 수성구 범어동 179번지
A45: 27260-100193891 | B45: 27260 | C45: 두산위브더제니스 | D45: 107동 | E45: 54 | F45: 대구광역시 수성구 범어동 179번지
A46: 27260-100194599 | B46: 27260 | C46: 두산위브더제니스 | D46: 104동 | E46: 53 | F46: 대구광역시 수성구 범어동 179번지
A47: 27260-100194748 | B47: 27260 | C47: 두산위브더제니스 | D47: 105동 | E47: 53 | F47: 대구광역시 수성구 범어동 179번지
A48: 27260-100194307 | B48: 27260 | C48: 두산위브더제니스 | D48: 109동 | E48: 52 | F48: 대구광역시 수성구 범어동 179번지
A49: 27260-100195049 | B49: 27260 | C49: 두산위브더제니스 | D49: 108동 | E49: 52 | F49: 대구광역시 수성구 범어동 179번지
...

Sheet 8.고층건축물BACKUP(건축+주택)
A1: 구분 | B1: SIGUNGU_CD | C1: F_PLAT_PLC_PRT(X03.SIGUNGU_CD,X03.BJDONG_CD,X03.PLAT_GB_CD,X03.BUN,X03.JI,X03.SPLOT_NM,X03.BLOCK,X03.LOT) | D1: BLD_NM | E1: DONG_NM | F1: GRND_FLR_CNT
A2: 건축 | B2: 11710 | C2: 서울특별시 송파구 신천동 29번지 | D2: 제2롯데월드신축공사 | E2: 제2롯데월드 | F2: 123
A3: 주택 | B3: 26350 | C3: 부산광역시 해운대구 중동 블록 해운대관광리조트 도시개발구역지구 I블록 1로트 | D3: 해운대 관광리조트 | E3: 랜드마크타워 | F3: 108
A4: 건축 | B4: 26110 | C4: 부산광역시 중구 중앙동7가 20-1번지 | D4: 부산롯데타운 | E4: 타워동 | F4: 107
A5: 주택 | B5: 26350 | C5: 부산광역시 해운대구 중동 블록 해운대관광리조트 도시개발구역지구 I블록 1로트 | D5: 해운대 관광리조트 | E5: 주거타워 A동 | F5: 87
A6: 주택 | B6: 26350 | C6: 부산광역시 해운대구 중동 블록 해운대관광리조트 도시개발구역지구 I블록 1로트 | D6: 해운대 관광리조트 | E6: 주거타워 B동 | F6: 87
A7: 건축 | B7: 26290 | C7: 부산광역시 남구 문현동 1229-2번지 | D7: 부산국제금융센터 복합개발사업 | E7: 주건축물제1동 | F7: 63
A8: 주택 | B8: 41287 | C8: 경기도 고양시 일산서구 탄현동 297번지 | D8: 공동주택 | E8: 105 | F8: 59
A9: 주택 | B9: 41287 | C9: 경기도 고양시 일산서구 탄현동 297번지 | D9: 공동주택 | E9: 104 | F9: 57
A10: 주택 | B10: 41287 | C10: 경기도 고양시 일산서구 탄현동 297번지 | D10: 공동주택 | E10: 103 | F10: 55
A11: 주택 | B11: 41287 | C11: 경기도 고양시 일산서구 탄현동 297번지 | D11: 공동주택 | E11: 106 | F11: 54
A12: 주택 | B12: 41287 | C12: 경기도 고양시 일산서구 탄현동 297번지 | D12: 공동주택 | E12: 102 | F12: 54
A13: 주택 | B13: 41287 | C13: 경기도 고양시 일산서구 탄현동 297번지 | D13: 공동주택 | E13: 107 | F13: 53
A14: 주택 | B14: 41287 | C14: 경기도 고양시 일산서구 탄현동 297번지 | D14: 공동주택 | E14: 101 | F14: 53
A15: 주택 | B15: 28200 | C15: 인천광역시 남동구 논현동 블록 소래논현도시개발지구지구 C10블록블록 | D15: 인천 소래논현구역 C10블록 주상복합 신축공사 | E15: A | F15: 51
A16: 주택 | B16: 41287 | C16: 경기도 고양시 일산서구 탄현동 297번지 | D16: 공동주택 | E16: 108 | F16: 51
A17: 건축 | B17: 44200 | C17: 충청남도 아산시 배방읍 장재리 블록 아산배방택지개발사업지구 일반상업지역내 특별계획구역지구 4블록 | D17: 싸이클론타워 | E17: 싸이클론타워 | F17: 51
A18: 건축 | B18: 30200 | C18: 대전광역시 유성구 용산동 579번지 | D18: DTV ST 블럭호텔 | E18: Edifice-WHITE(104) | F18: 50
A19: 주택 | B19: 30230 | C19: 대전광역시 대덕구 석봉동 블록 구)풍한방직 이전적지 도시개발사업지구 A-1블록 | D19: 금강풍림엑슬루타워 | E19: 111동 | F19: 50
A20: 주택 | B20: 30230 | C20: 대전광역시 대덕구 석봉동 블록 구)풍한방직 이전적지 도시개발사업지구 A-1블록 | D20: 금강풍림엑슬루타워 | E20: 110동 | F20: 50
A21: 주택 | B21: 30230 | C21: 대전광역시 대덕구 석봉동 블록 구)풍한방직 이전적지 도시개발사업지구 A-1블록 | D21: 금강풍림엑슬루타워 | E21: 103동 | F21: 50
A22: 주택 | B22: 30230 | C22: 대전광역시 대덕구 석봉동 블록 구)풍한방직 이전적지 도시개발사업지구 A-1블록 | D22: 금강풍림엑슬루타워 | E22: 107동 | F22: 50
A23: 주택 | B23: 30230 | C23: 대전광역시 대덕구 석봉동 블록 구)풍한방직 이전적지 도시개발사업지구 A-1블록 | D23: 금강풍림엑슬루타워 | E23: 105동 | F23: 50
A24: 주택 | B24: 30230 | C24: 대전광역시 대덕구 석봉동 블록 구)풍한방직 이전적지 도시개발사업지구 A-1블록 | D24: 금강풍림엑슬루타워 | E24: 108동 | F24: 50
A25: 주택 | B25: 30230 | C25: 대전광역시 대덕구 석봉동 블록 구)풍한방직 이전적지 도시개발사업지구 A-1블록 | D25: 금강풍림엑슬루타워 | E25: 102동 | F25: 50
A26: 주택 | B26: 30230 | C26: 대전광역시 대덕구 석봉동 블록 구)풍한방직 이전적지 도시개발사업지구 A-1블록 | D26: 금강풍림엑슬루타워 | E26: 106동 | F26: 50
A27: 주택 | B27: 28200 | C27: 인천광역시 남동구 논현동 블록 소래논현도시개발지구지구 C10블록블록 | D27: 인천 소래논현구역 C10블록 주상복합 신축공사 | E27: B | F27: 48
A28: 건축 | B28: 31110 | C28: 울산광역시 중구 성남동 196-21번지 | D28: 성남동주상복합 | E28: A | F28: 48
... A50: 건축 | B50: 48170 | C50: 경상남도 진주시 강남동 181-1번지 | D50: 진주시 강남동 주거복합 | E50: 강남동 주거복합 | F50: 35
A51: 건축 | B51: 31140 | C51: 울산광역시 남구 신정동 1127-3번지 | D51: 남구 신정동 주상복합 | E51: 1 | F51: 33
A52: 건축 | B52: 46130 | C52: 전라남도 여수시 소호동 산 99번지 | D52: 여수오션리조트 | E52: 관광호텔동 | F52: 33
A53: 건축 | B53: 28200 | C53: 인천광역시 남동구 논현동 블록 논현(2)택지개발사업지구상업용지C12-2지구 | D53: 논현2지구 오피스텔 신축공사 | E53: C동 | F53: 32
A54: 건축 | B54: 43710 | C54: 충청북도 청원군 오창읍 양청리 808-2번지 | D54: 오창양청리000호텔 | E54: 오창양청리000호텔 | F54: 32
A55: 건축 | B55: 46110 | C55: 전라남도 목포시 남교동 111-9번지 | D55: 남교동 111-9 공동주택 (한국토지주택공사) | E55: 목포남교주상관복합건축 | F55: 31
A56: 건축 | B56: 46170 | C56: 전라남도 나주시 금천면 블록 광주전남공동혁신 도시개발사업지구지구 이전1블록 | D56: KEPCO 본사 신사옥 | E56: 본관 | F56: 31
A57: 주택 | B57: 46230 | C57: 전라남도 광양시 중동 1601번지 | D57: 대광 로제비앙 2차 아파트 신축공사 | E57: 201 | F57: 30
A58: 건축 | B58: 48170 | C58: 경상남도 진주시 평거동 139-5번지 | D58: 진주 평거동 OO주상복합 신축공사 | E58: 101동 | F58: 30
A59: 주택 | B59: 46230 | C59: 전라남도 광양시 광양읍 용강리 919번지 | E59: 104동 | F59: 28
A60: 주택 | B60: 46230 | C60: 전라남도 광양시 광양읍 용강리 919번지 | E60: 102동 | F60: 28
A61: 주택 | B61: 46230 | C61: 전라남도 광양시 광양읍 용강리 919번지 | E61: 103동 | F61: 28
...

Sheet 5-1. 경과년수별(시도별)
A1: 5-1. 2023년 경과년수별 건축물 현황
A2: [기준] 기타 : 사용승일일(항목) 값 누락 또는 오기
A3: [기준] 10년미만(2015년-2023년), 10년이상-15년미만(2010년-2014년), 15년이상-20년미만(2005년-2009년)
A4: 20년이상-25년미만(2000년-2004년), 25년이상-30년미만(1995년-1999년), 30년이상-35년미만(1990년-1994년), 35년이상(~1989년)
O5: (단위 : 동, ㎡)
B6: 구분 | D6: 합계 | F6: 주거용 | H6: 상업용 | J6: 공업용 | L6: 교육 및 사회용 | N6: 기타
D7: 동수 | E7: 연면적 | F7: 동수 | G7: 연면적 | H7: 동수 | I7: 연면적 | J7: 동수 | K7: 연면적 | L7: 동수 | M7: 연면적 | N7: 동수 | O7: 연면적
B8: 전체 | C8: 합계 | D8: 7391084 | E8: 4.2276607e+09 | F8: 4576735 | G8: 1.9505563e+09 | H8: 1392582 | I8: 9.3468869e+08 | J8: 345087 | K8: 4.6514802e+08 | L8: 203489 | M8: 3.7664541e+08 | N8: 873191 | O8: 5.0062229e+08
C9: 10년미만 | D9: 1178853 | E9: 1.0119716e+09 | F9: 550896 | G9: 4.432101e+08 | H9: 298633 | I9: 2.606841e+08 | J9: 83958 | K9: 1.2141079e+08 | L9: 31073 | M9: 64384983 | N9: 214293 | O9: 1.222816e+08
C10: 10 ~ 15년 미만 | D10: 636450 | E10: 4.8913834e+08 | F10: 314443 | G10: 2.1255684e+08 | H10: 144237 | I10: 1.0236882e+08 | J10: 52951 | K10: 71134100 | L10: 24292 | M10: 48759736 | N10: 100527 | O10: 54318841
C11: 15 ~ 20년 미만 | D11: 555637 | E11: 5.0986053e+08 | F11: 232115 | G11: 2.3527217e+08 | H11: 141454 | I11: 1.0473407e+08 | J11: 50243 | K11: 64036096 | L11: 28832 | M11: 56129681 | N11: 102993 | O11: 49688516
C12: 20 ~ 25년 미만 | D12: 626876 | E12: 5.3599378e+08 | F12: 316292 | G12: 2.6447105e+08 | H12: 152077 | I12: 1.2540835e+08 | J12: 48351 | K12: 51174307 | L12: 26325 | M12: 52708687 | N12: 83831 | O12: 42231380
C13: 25 ~ 30년 미만 | D13: 743422 | E13: 5.8389122e+08 | F13: 399043 | G13: 2.6547915e+08 | H13: 147120 | I13: 1.0431984e+08 | J13: 35366 | K13: 47851445 | L13: 27960 | M13: 52909061 | N13: 133933 | O13: 1.1333173e+08
C14: 30 ~ 35년 미만 | D14: 705941 | E14: 5.000757e+08 | F14: 447007 | G14: 2.5363226e+08 | H14: 139231 | I14: 99552052 | J14: 29088 | K14: 48512475 | L14: 16107 | M14: 27237783 | N14: 74508 | O14: 71141134
C15: 35년 이상 | D15: 2444039 | E15: 5.1637335e+08 | F15: 1934662 | G15: 2.4856399e+08 | H15: 314890 | I15: 1.2720253e+08 | J15: 36521 | K15: 49777728 | L15: 33934 | M15: 54374004 | N15: 124032 | O15: 36455096
C16: 기타 | D16: 499866 | E16: 80356195 | F16: 382277 | G16: 27370715 | H16: 54940 | I16: 10418921 | J16: 8609 | K16: 11251085 | L16: 14966 | M16: 20141474 | N16: 39074 | O16: 11174000
B17: 서울특별시 | C17: 합계 | D17: 579408 | E17: 5.9422332e+08 | F17: 428325 | G17: 3.0847809e+08 | H17: 127876 | I17: 1.8678264e+08 | J17: 2322 | K17: 14552067 | L17: 16367 | M17: 63430315 | N17: 4518 | O17: 20980204
C18: 10년미만 | D18: 52244 | E18: 95584771 | F18: 39334 | G18: 46627352 | H18: 10430 | I18: 32574937 | J18: 190 | K18: 5523317.7 | L18: 1692 | M18: 8525893.6 | N18: 598 | O18: 2333270.4
C19: 10 ~ 15년 미만 | D19: 29492 | E19: 55389229 | F19: 21737 | G19: 26371509 | H19: 5817 | I19: 16751157 | J19: 91 | K19: 2376894.7 | L19: 1417 | M19: 7855157.7 | N19: 430 | O19: 2034510.7
C20: 15 ~ 20년 미만 | D20: 26325 | E20: 70435843 | F20: 17002 | G20: 34093198 | H20: 6992 | I20: 22816703 | J20: 135 | K20: 3059108.6 | L20: 1864 | M20: 8447370.2 | N20: 332 | O20: 2019463.1
C21: 20 ~ 25년 미만 | D21: 55206 | E21: 93375469 | F21: 41974 | G21: 58871383 | H21: 10499 | I21: 22510119 | J21: 209 | K21: 1877062 | L21: 2064 | M21: 7069908.2 | N21: 460 | O21: 3046996.4
C22: 25 ~ 30년 미만 | D22: 53257 | E22: 79175045 | F22: 40550 | G22: 45981813 | H22: 9765 | I22: 18914084 | J22: 96 | K22: 420610.7 | L22: 2326 | M22: 8857580.3 | N22: 520 | O22: 5000956.7
C23: 30 ~ 35년 미만 | D23: 114685 | E23: 74270751 | F23: 93694 | G23: 41701462 | H23: 18893 | I23: 25172126 | J23: 60 | K23: 176304.39 | L23: 1625 | M23: 4869941.3 | N23: 413 | O23: 2350917.5
C24: 35년 이상 | D24: 216858 | E24: 1.2003683e+08 | F24: 152628 | G24: 53377905 | H24: 57159 | I24: 45849392 | J24: 1270 | K24: 968268.85 | L24: 4322 | M24: 15866429 | N24: 1479 | O24: 3974837.2
C25: 기타 | D25: 31341 | E25: 5955376.6 | F25: 21406 | G25: 1453468.1 | H25: 8321 | I25: 2194121.6 | J25: 271 | K25: 150499.86 | L25: 1057 | M25: 1938035.1 | N25: 286 | O25: 219251.94
B26: 부산광역시 | C26: 합계 | D26: 348634 | E26: 2.5584108e+08 | F26: 236696 | G26: 1.2462408e+08 | H26: 73754 | I26: 64595346 | J26: 15784 | K26: 19867250 | L26: 9260 | M26: 23981385 | N26: 13140 | O26: 22773015
C27: 10년미만 | D27: 26162 | E27: 47346526 | F27: 9937 | G27: 23182408 | H27: 11312 | I27: 15027340 | J27: 2761 | K27: 4231365.4 | L27: 912 | M27: 2949785.7 | N27: 1240 | O27: 1955627.6
C28: 10 ~ 15년 미만 | D28: 19246 | E28: 31418460 | F28: 8599 | G28: 13820393 | H28: 6828 | I28: 10263216 | J28: 2273 | K28: 3755408.9 | L28: 783 | M28: 2545749.9 | N28: 763 | O28: 1033692.1
C29: 15 ~ 20년 미만 | D29: 13275 | E29: 27735409 | F29: 3900 | G29: 13611068 | H29: 5029 | I29: 6701209.3 | J29: 2252 | K29: 2773016.5 | L29: 1029 | M29: 3023744.5 | N29: 1065 | O29: 1626370.8
C30: 20 ~ 25년 미만 | D30: 22951 | E30: 30328709 | F30: 11297 | G30: 14950694 | H30: 6551 | I30: 7349275.4 | J30: 2356 | K30: 2983479.4 | L30: 1002 | M30: 2864573 | N30: 1745 | O30: 2180687.2
C31: 25 ~ 30년 미만 | D31: 22159 | E31: 39888356 | F31: 13521 | G31: 18904122 | H31: 5477 | I31: 6350377.5 | J31: 760 | K31: 1242358.4 | L31: 1060 | M31: 2638491.7 | N31: 1341 | O31: 10753006
C32: 30 ~ 35년 미만 | D32: 37129 | E32: 28820658 | F32: 25513 | G32: 16199472 | H32: 8593 | I32: 6827555 | J32: 1195 | K32: 1538833.5 | L32: 912 | M32: 1595594.9 | N32: 916 | O32: 2659202.3
C33: 35년 이상 | D33: 174419 | E33: 46105721 | F33: 137120 | G33: 22498920 | H33: 25938 | I33: 11138355 | J33: 3442 | K33: 2949002.3 | L33: 2934 | M33: 7349287.5 | N33: 4985 | O33: 2170155.6
C34: 기타 | D34: 33293 | E34: 4197241.5 | F34: 26809 | G34: 1457005.6 | H34: 4026 | I34: 938018.06 | J34: 745 | K34: 393785.85 | L34: 628 | M34: 1014158.3 | N34: 1085 | O34: 394273.78
B35: 대구광역시 | C35: 합계 | D35: 256241 | E35: 1.8144026e+08 | F35: 168976 | G35: 95283309 | H35: 54117 | I35: 45453596 | J35: 13375 | K35: 16290192 | L35: 6637 | M35: 16051156 | N35: 13136 | O35: 8362007.8
C36: 10년미만 | D36: 25759 | E36: 40389909 | F36: 12559 | G36: 19572075 | H36: 8502 | I36: 13118460 | J36: 1749 | K36: 3350409.3 | L36: 987 | M36: 2964080.5 | N36: 1962 | O36: 1384884.4
C37: 10 ~ 15년 미만 | D37: 16748 | E37: 16003210 | F37: 8434 | G37: 7500508.5 | H37: 4675 | I37: 3615392.4 | J37: 1710 | K37: 2280203.4 | L37: 668 | M37: 1904109.5 | N37: 1261 | O37: 702996.21
C38: 15 ~ 20년 미만 | D38: 14216 | E38: 22367559 | F38: 6386 | G38: 14491519 | H38: 3952 | I38: 3170844.2 | J38: 1524 | K38: 1715932.7 | L38: 824 | M38: 2081190.5 | N38: 1530 | O38: 908072.95
C39: 20 ~ 25년 미만 | D39: 22306 | E39: 22262755 | F39: 12932 | G39: 12117882 | H39: 4949 | I39: 4800824.7 | J39: 2029 | K39: 1740152.4 | L39: 889 | M39: 2670715.7 | N39: 1507 | O39: 933180.89
C40: 25 ~ 30년 미만 | D40: 25674 | E40: 25650328 | F40: 16333 | G40: 14519580 | H40: 5083 | I40: 5287621.8 | J40: 1226 | K40: 1572686.3 | L40: 1015 | M40: 2386757.5 | N40: 2017 | O40: 1883682.7
...

Sheet 5-2. 30년이상 건축물(시군구별) 
A1: 5-2. 2023년 30년이상 건축물 현황(시군구별)
A2: [기준] 30년 이상 건축물 : 사용승인 30년이상 경과(~1994년)
I3: (단위 : ㎡)
B4: 시도 | C4: 시군구 | D4: 전체 건축물 | G4: 주거용 건축물
D5: 연면적 | E5: 30년 이상 건축물 연면적 | F5: 노후 건축물 비율(%) | G5: 연면적 | H5: 30년 이상 건축물 연면적 | I5: 노후 건축물 비율(%)
B6: 서울 | C6: 종로구 | D6: 19667796 | E6: 8970552.7 | F6: =E6/D6 -> 0.45610362 | G6: 5067119.8 | H6: 1664178.2 | I6: =H6/G6 -> 0.32842684
B7: 서울 | C7: 중구 | D7: 22465284 | E7: 9888314.5 | F7: =E7/D7 -> 0.44015978 | G7: 4577012 | H7: 1094010.6 | I7: =H7/G7 -> 0.23902287
B8: 서울 | C8: 용산구 | D8: 17734347 | E8: 6522356.5 | F8: =E8/D8 -> 0.36778103 | G8: 8877857.2 | H8: 3171784.4 | I8: =H8/G8 -> 0.35726914
B9: 서울 | C9: 성동구 | D9: 19934802 | E9: 5319703.8 | F9: =E9/D9 -> 0.26685512 | G9: 9364345.5 | H9: 2584260.9 | I9: =H9/G9 -> 0.27596813
B10: 서울 | C10: 광진구 | D10: 17097833 | E10: 5937988.2 | F10: =E10/D10 -> 0.34729478 | G10: 9971910.5 | H10: 3302419.7 | I10: =H10/G10 -> 0.33117222
B11: 서울 | C11: 동대문구 | D11: 19004726 | E11: 6301304.4 | F11: =E11/D11 -> 0.33156513 | G11: 10433954 | H11: 2767343.4 | I11: =H11/G11 -> 0.26522479
B12: 서울 | C12: 중랑구 | D12: 22167195 | E12: 5418116.4 | F12: =E12/D12 -> 0.24442048 | G12: 14191795 | H12: 3464884.6 | I12: =H12/G12 -> 0.24414703
B13: 서울 | C13: 성북구 | D13: 21591756 | E13: 5614063.3 | F13: =E13/D13 -> 0.26000957 | G13: 14285216 | H13: 3129073.4 | I13: =H13/G13 -> 0.21904278
B14: 서울 | C14: 강북구 | D14: 12826476 | E14: 5127326.7 | F14: =E14/D14 -> 0.39974555 | G14: 8561701.1 | H14: 3328256.7 | I14: =H14/G14 -> 0.38873778
B15: 서울 | C15: 도봉구 | D15: 15932860 | E15: 5999687.7 | F15: =E15/D15 -> 0.37656063 | G15: 10149854 | H15: 4391814.6 | I15: =H15/G15 -> 0.43269733
B16: 서울 | C16: 노원구 | D16: 22673444 | E16: 10702770 | F16: =E16/D16 -> 0.47203986 | G16: 15807225 | H16: 7956595.5 | I16: =H16/G16 -> 0.50335181
B17: 서울 | C17: 은평구 | D17: 20812060 | E17: 5486688.7 | F17: =E17/D17 -> 0.26363025 | G17: 14383417 | H17: 3645033.1 | I17: =H17/G17 -> 0.25341914
... B80: 울산 | C80: 울주군 | D80: 23758512 | E80: 4259565.8 | F80: =E80/D80 -> 0.17928588 | G80: 8761591.6 | H80: 1732548.7 | I80: =H80/G80 -> 0.19774361
B81: 세종 | D81: 31939700 | E81: 2586088.7 | F81: =E81/D81 -> 0.080967846 | G81: 16035868 | H81: 972831.76 | I81: =H81/G81 -> 0.060665988
B82: 경기 | C82: 수원시 장안구 | D82: 14351073 | E82: 3617197.9 | F82: =E82/D82 -> 0.2520507 | G82: 9234494.4 | H82: 2117118.3 | I82: =H82/G82 -> 0.22926196
B83: 경기 | C83: 수원시 권선구 | D83: 22456259 | E83: 3345328.7 | F83: =E83/D83 -> 0.14897089 | G83: 13029104 | H83: 2239497.8 | I83: =H83/G83 -> 0.17188425
B84: 경기 | C84: 수원시 팔달구 | D84: 13606402 | E84: 3945437.2 | F84: =E84/D84 -> 0.28996917 | G84: 6549463.1 | H84: 1717862.3 | I84: =H84/G84 -> 0.26229055
B85: 경기 | C85: 수원시 영통구 | D85: 28283351 | E85: 3180737.8 | F85: =E85/D85 -> 0.11245972 | G85: 12763090 | H85: 1663993.5 | I85: =H85/G85 -> 0.13037544
B86: 경기 | C86: 성남시 수정구 | D86: 13922632 | E86: 3388500.7 | F86: =E86/D86 -> 0.24338076 | G86: 6734816.9 | H86: 1965900.3 | I86: =H86/G86 -> 0.29190107
B87: 경기 | C87: 성남시 중원구 | D87: 12755613 | E87: 3763440.1 | F87: =E87/D87 -> 0.29504188 | G87: 6133313.7 | H87: 2180742.5 | I87: =H87/G87 -> 0.35555699
B88: 경기 | C88: 성남시 분당구 | D88: 63820015 | E88: 29864392 | F88: =E88/D88 -> 0.46794712 | G88: 22543218 | H88: 11582972 | I88: =H88/G88 -> 0.51381183
B89: 경기 | C89: 의정부시 | D89: 25549268 | E89: 5244510.7 | F89: =E89/D89 -> 0.20527049 | G89: 15412294 | H89: 3195101.5 | I89: =H89/G89 -> 0.20730863
B90: 경기 | C90: 안양시 만안구 | D90: 13449042 | E90: 4214755.6 | F90: =E90/D90 -> 0.31338704 | G90: 7032184.8 | H90: 1921643.8 | I90: =H90/G90 -> 0.27326412
B91: 경기 | C91: 안양시 동안구 | D91: 21644106 | E91: 7650269.2 | F91: =E91/D91 -> 0.35345738 | G91: 10242240 | H91: 4821699 | I91: =H91/G91 -> 0.47076605
B92: 경기 | C92: 부천시 | D92: 54335959 | E92: 18581923 | F92: =E92/D92 -> 0.34198205 | G92: 25536864 | H92: 9014931.6 | I92: =H92/G92 -> 0.35301639
B93: 경기 | C93: 광명시 | D93: 16273159 | E93: 5791378.4 | F93: =E93/D93 -> 0.35588533 | G93: 9038913.5 | H93: 3628353.3 | I93: =H93/G93 -> 0.40141476
... B255: 제주 | C255: 서귀포시 | D255: 20391188 | E255: 4171865.5 | F255: =E255/D255 -> 0.20459158 | G255: 7470531.6 | H255: 1923802.7 | I255: =H255/G255 -> 0.25751885

Sheet 6. 말소
A1: =목차!B9 -> 6. 2023년 말소 건축물 용도별 현황
A2: [기준] 기타 : 사용승일일(항목) 값 누락 또는 오기
A3: [기준] 기간산출방식 : 말소일 - 사용승인일
A4: [기준] 10년미만(2015년-2023년), 10년이상-15년미만(2010년-2014년), 15년이상-20년미만(2005년-2009년)
A5: 20년이상-25년미만(2000년-2004년), 25년이상-30년미만(1995년-1999년), 30년이상-35년미만(1990년-1994년), 35년이상(~1989년)
O6: (단위 : 동, ㎡)
B7: 구분 | D7: 합계 | F7: 주거용 | H7: 상업용 | J7: 공업용 | L7: 교육 및 사회용 | N7: 기타
D8: 동수 | E8: 연면적 | F8: 동수 | G8: 연면적 | H8: 동수 | I8: 연면적 | J8: 동수 | K8: 연면적 | L8: 동수 | M8: 연면적 | N8: 동수 | O8: 연면적
B9: 전체 | C9: 합계 | D9: 47701 | E9: 10640986 | F9: 32207 | G9: 4745262.9 | H9: 8838 | I9: 3168407.7 | J9: 1259 | K9: 923184.67 | L9: 593 | M9: 460867.34 | N9: 4804 | O9: 1343263.8
C10: 10년미만 | D10: 1937 | E10: 656498.53 | F10: 515 | G10: 290065.46 | H10: 777 | I10: 201753.43 | J10: 66 | K10: 35013.72 | L10: 21 | M10: 31923.44 | N10: 558 | O10: 97742.472
C11: 10 ~ 15년 미만 | D11: 1489 | E11: 373439.35 | F11: 417 | G11: 72640.336 | H11: 631 | I11: 164806.52 | J11: 72 | K11: 35582.98 | L11: 33 | M11: 14525.844 | N11: 336 | O11: 85883.67
C12: 15 ~ 20년 미만 | D12: 2213 | E12: 740837.47 | F12: 707 | G12: 145938.48 | H12: 854 | I12: 305380.46 | J12: 125 | K12: 104903.29 | L12: 49 | M12: 61184.13 | N12: 478 | O12: 123431.12
C13: 20 ~ 25년 미만 | D13: 2989 | E13: 1103109.9 | F13: 1113 | G13: 281689.66 | H13: 966 | I13: 425268.41 | J13: 185 | K13: 117346.38 | L13: 71 | M13: 49495.459 | N13: 654 | O13: 229309.98
C14: 25 ~ 30년 미만 | D14: 4274 | E14: 1341065.3 | F14: 1933 | G14: 400342.73 | H14: 1202 | I14: 462998.43 | J14: 185 | K14: 115265.1 | L14: 123 | M14: 92639.772 | N14: 831 | O14: 269819.27
C15: 30 ~ 35년 미만 | D15: 4645 | E15: 1520688.5 | F15: 3021 | G15: 661561.01 | H15: 956 | I15: 482615.92 | J15: 158 | K15: 169818.44 | L15: 71 | M15: 41251.597 | N15: 439 | O15: 165441.49
C16: 35년 이상 | D16: 18177 | E16: 3961681.3 | F16: 14468 | G16: 2299504.3 | H16: 2534 | I16: 998001.92 | J16: 361 | K16: 304427.58 | L16: 147 | M16: 138323.97 | N16: 667 | O16: 221423.54
C17: 기타 | D17: 11977 | E17: 943666.1 | F17: 10033 | G17: 593520.88 | H17: 918 | I17: 127582.63 | J17: 107 | K17: 40827.17 | L17: 78 | M17: 31523.13 | N17: 841 | O17: 150212.3
B18: 서울특별시 | C18: 합계 | D18: 4789 | E18: 2130368.1 | F18: 3416 | G18: 1129880.4 | H18: 1221 | I18: 822674.83 | J18: 39 | K18: 39676.378 | L18: 59 | M18: 83951.415 | N18: 54 | O18: 54185.156
C19: 10년미만 | D19: 27 | E19: 31178.709 | F19: 15 | G19: 18708.098 | H19: 11 | I19: 12207.651 | J19: 0 | K19: 0 | L19: 1 | M19: 262.96 | N19: 0 | O19: 0
C20: 10 ~ 15년 미만 | D20: 41 | E20: 16655.44 | F20: 9 | G20: 3293.08 | H20: 31 | I20: 12867.64 | J20: 0 | K20: 0 | L20: 0 | M20: 0 | N20: 1 | O20: 494.72
C21: 15 ~ 20년 미만 | D21: 88 | E21: 74800.118 | F21: 35 | G21: 10426.81 | H21: 47 | I21: 56241.95 | J21: 2 | K21: 5189.538 | L21: 1 | M21: 2003 | N21: 3 | O21: 938.82
C22: 20 ~ 25년 미만 | D22: 195 | E22: 121378.02 | F22: 109 | G22: 54259.993 | H22: 80 | I22: 62534.74 | J22: 1 | K22: 1797.12 | L22: 4 | M22: 1755.6 | N22: 1 | O22: 1030.57
C23: 25 ~ 30년 미만 | D23: 462 | E23: 225887.45 | F23: 336 | G23: 106076.98 | H23: 115 | I23: 101485.54 | J23: 0 | K23: 1270.05 | L23: 8 | M23: 10226.325 | N23: 3 | O23: 6828.56
C24: 30 ~ 35년 미만 | D24: 879 | E24: 364690.2 | F24: 736 | G24: 221919.84 | H24: 131 | I24: 132282.22 | J24: 1 | K24: 1490.5 | L24: 8 | M24: 3817.31 | N24: 3 | O24: 5180.336
C25: 35년 이상 | D25: 2773 | E25: 1266263 | F25: 1993 | G25: 704698.09 | H25: 687 | I25: 430823.88 | J25: 30 | K25: 28677.33 | L25: 36 | M25: 65091.36 | N25: 27 | O25: 36972.34
C26: 기타 | D26: 324 | E26: 29515.2 | F26: 183 | G26: 10497.47 | H26: 119 | I26: 14231.22 | J26: 5 | K26: 1251.84 | L26: 1 | M26: 794.86 | N26: 16 | O26: 2739.81
B27: 부산광역시 | C27: 합계 | D27: 3676 | E27: 760198.49 | F27: 2547 | G27: 346241.44 | H27: 663 | I27: 266673.3 | J27: 55 | K27: 32762.733 | L27: 28 | M27: 26647.555 | N27: 383 | O27: 87873.456
C28: 10년미만 | D28: 48 | E28: 25572.013 | F28: 16 | G28: 2349.11 | H28: 22 | I28: 12207.713 | J28: 0 | K28: 0 | L28: 4 | M28: 4504.68 | N28: 6 | O28: 6510.51
C29: 10 ~ 15년 미만 | D29: 149 | E29: 48761.049 | F29: 38 | G29: 8507.4711 | H29: 100 | I29: 34436.178 | J29: 2 | K29: 2582.24 | L29: 0 | M29: 0 | N29: 9 | O29: 3235.16
C30: 15 ~ 20년 미만 | D30: 201 | E30: 76729.12 | F30: 38 | G30: 6976.58 | H30: 124 | I30: 45855.105 | J30: 1 | K30: 2703.18 | L30: 3 | M30: 8597.72 | N30: 35 | O30: 12596.535
C31: 20 ~ 25년 미만 | D31: 228 | E31: 87235.99 | F31: 79 | G31: 18132.785 | H31: 57 | I31: 36242.09 | J31: 4 | K31: 4101.12 | L31: 1 | M31: 1081.08 | N31: 87 | O31: 27678.915
C32: 25 ~ 30년 미만 | D32: 233 | E32: 73291.026 | F32: 153 | G32: 33856.497 | H32: 39 | I32: 26333.549 | J32: 2 | K32: 259.2 | L32: 7 | M32: 5623.06 | N32: 32 | O32: 7218.72
C33: 30 ~ 35년 미만 | D33: 317 | E33: 74750.93 | F33: 230 | G33: 35936.085 | H33: 65 | I33: 30820.565 | J33: 3 | K33: 1953.31 | L33: 2 | M33: 2931.06 | N33: 17 | O33: 3109.91
C34: 35년 이상 | D34: 1676 | E34: 329054.31 | F34: 1392 | G34: 209930.45 | H34: 210 | I34: 74603.181 | J34: 34 | K34: 19441.173 | L34: 6 | M34: 3314.955 | N34: 34 | O34: 21764.546
C35: 기타 | D35: 824 | E35: 44804.055 | F35: 601 | G35: 30552.465 | H35: 46 | I35: 6174.92 | J35: 9 | K35: 1722.51 | L35: 5 | M35: 595 | N35: 163 | O35: 5759.16
B36: 대구광역시 | C36: 합계 | D36: 1945 | E36: 812033.28 | F36: 1383 | G36: 430011.36 | H36: 383 | I36: 242982.21 | J36: 72 | K36: 58367.99 | L36: 20 | M36: 23955.035 | N36: 87 | O36: 56716.677
C37: 10년미만 | D37: 61 | E37: 174275.18 | F37: 19 | G37: 118238.34 | H37: 29 | I37: 47926.005 | J37: 1 | K37: 313.2 | L37: 2 | M37: 3130.96 | N37: 10 | O37: 4666.672
C38: 10 ~ 15년 미만 | D38: 57 | E38: 26751.23 | F38: 9 | G38: 5612.215 | H38: 37 | I38: 15205.965 | J38: 2 | K38: 1085.7 | L38: 2 | M38: 3610.09 | N38: 7 | O38: 1237.26
C39: 15 ~ 20년 미만 | D39: 39 | E39: 9217.4 | F39: 10 | G39: 1855.91 | H39: 23 | I39: 6501.58 | J39: 0 | K39: 0 | L39: 0 | M39: 0 | N39: 6 | O39: 859.91
C40: 20 ~ 25년 미만 | D40: 99 | E40: 107939.82 | F40: 47 | G40: 20781.696 | H40: 32 | I40: 52617.28 | J40: 2 | K40: 2288.36 | L40: 1 | M40: 1663.53 | N40: 17 | O40: 30588.95
...

Sheet 7-1. 층수별
A1: 7-1. 2023년 층수별 현황
L2: (단위 : 동)
B3: 시도명 | C3: 합계 | D3: 1층 | E3: 2~4층 | F3: 5층 | G3: 6~10층 | H3: 11~20층 | I3: 21~30층 | J3: 31 ~ 49층 | K3: 50층 이상 | L3: 기타
B4: 합계 | C4: =SUM(D4:L4) -> 7391084 | D4: =SUM(D5:D21) -> 4489003 | E4: =SUM(E5:E21) -> 2462327 | F4: =SUM(F5:F21) -> 185860 | G4: =SUM(G5:G21) -> 100671 | H4: =SUM(H5:H21) -> 100323 | I4: =SUM(I5:I21) -> 30106 | J4: =SUM(J5:J21) -> 4184 | K4: =SUM(K5:K21) -> 132 | L4: =SUM(L5:L21) -> 18478
B5: 서울특별시 | C5: =SUM(D5:L5) -> 579408 | D5: 101428 | E5: 350553 | F5: 66712 | G5: 37274 | H5: 17881 | I5: 4105 | J5: 554 | K5: 24 | L5: 877
B6: 부산광역시 | C6: =SUM(D6:L6) -> 348634 | D6: 136999 | E6: 177503 | F6: 14226 | G6: 9724 | H6: 5776 | I6: 2982 | J6: 592 | K6: 41 | L6: 791
B7: 대구광역시 | C7: =SUM(D7:L7) -> 256241 | D7: 96045 | E7: 143764 | F7: 6640 | G7: 2869 | H7: 4544 | I7: 1445 | J7: 261 | K7: 17 | L7: 656
B8: 인천광역시 | C8: =SUM(D8:L8) -> 221783 | D8: 86241 | E8: 108933 | F8: 13050 | G8: 5317 | H8: 5169 | I8: 2029 | J8: 623 | K8: 19 | L8: 402
B9: 광주광역시 | C9: =SUM(D9:L9) -> 136197 | D9: 52856 | E9: 72706 | F9: 3607 | G9: 1849 | H9: 3894 | I9: 779 | J9: 95 | K9: 0 | L9: 411
B10: 대전광역시 | C10: =SUM(D10:L10) -> 131054 | D10: 46540 | E10: 73591 | F10: 4342 | G10: 2348 | H10: 2973 | I10: 904 | J10: 106 | K10: 8 | L10: 242
B11: 울산광역시 | C11: =SUM(D11:L11) -> 137107 | D11: 65392 | E11: 63151 | F11: 3002 | G11: 2263 | H11: 2153 | I11: 695 | J11: 141 | K11: 2 | L11: 308
B12: 세종특별자치시 | C12: =SUM(D12:L12) -> 35383 | D12: 24080 | E12: 8638 | F12: 321 | G12: 528 | H12: 1005 | I12: 632 | J12: 46 | K12: 0 | L12: 133
B13: 경기도 | C13: =SUM(D13:L13) -> 1265969 | D13: 639107 | E13: 524276 | F13: 40150 | G13: 18458 | H13: 28532 | I13: 10021 | J13: 1080 | K13: 19 | L13: 4326
B14: 강원특별자치도 | C14: =SUM(D14:L14) -> 437539 | D14: 314881 | E14: 112376 | F14: 3781 | G14: 1949 | H14: 3343 | I14: 414 | J14: 60 | K14: 0 | L14: 735
B15: 충청북도 | C15: =SUM(D15:L15) -> 407286 | D15: 294196 | E15: 103345 | F15: 3424 | G15: 1859 | H15: 3088 | I15: 788 | J15: 64 | K15: 0 | L15: 522
B16: 충청남도 | C16: =SUM(D16:L16) -> 564466 | D16: 434627 | E16: 114185 | F16: 4456 | G16: 2461 | H16: 4254 | I16: 1236 | J16: 134 | K16: 1 | L16: 3112
... B21: 제주특별자치도 | C21: =SUM(D21:L21) -> 189336 | D21: 122561 | E21: 61355 | F21: 2176 | G21: 2139 | H21: 531 | I21: 1 | J21: 1 | K21: 0 | L21: 572

Sheet 7-2. 면적별
A1: 7-2. 2023년 면적별 현황
K2: (단위 : 동)
B3: 시도명 | C3: 합계 | D3: 1백㎡미만 | E3: 1백㎡~2백㎡미만 | F3: 2백㎡~3백㎡미만 | G3: 3백㎡~5백㎡미만 | H3: 5백㎡~1천㎡미만 | I3: 1천㎡~3천㎡미만 | J3: 3천㎡~1만㎡미만 | K3: 1만㎡이상
B4: 합계 | C4: =SUM(D4:K4) -> 7391084 | D4: =SUM(D5:D21) -> 3226235 | E4: =SUM(E5:E21) -> 1661448 | F4: =SUM(F5:F21) -> 549368 | G4: =SUM(G5:G21) -> 811343 | H4: =SUM(H5:H21) -> 598013 | I4: =SUM(I5:I21) -> 301934 | J4: =SUM(J5:J21) -> 172921 | K4: =SUM(K5:K21) -> 69822
B5: 서울특별시 | C5: =SUM(D5:K5) -> 579408 | D5: 102441 | E5: 116806 | F5: 89734 | G5: 103060 | H5: 96458 | I5: 36986 | J5: 22733 | K5: 11190
B6: 부산광역시 | C6: =SUM(D6:K6) -> 348634 | D6: 142690 | E6: 90136 | F6: 22710 | G6: 34084 | H6: 27801 | I6: 16215 | J6: 9700 | K6: 5298
B7: 대구광역시 | C7: =SUM(D7:K7) -> 256241 | D7: 77957 | E7: 69983 | F7: 23473 | G7: 39901 | H7: 22710 | I7: 11305 | J7: 7412 | K7: 3500
B8: 인천광역시 | C8: =SUM(D8:K8) -> 221783 | D8: 66212 | E8: 43439 | F8: 20079 | G8: 34570 | H8: 29602 | I8: 13437 | J8: 9793 | K8: 4651
B9: 광주광역시 | C9: =SUM(D9:K9) -> 136197 | D9: 43873 | E9: 39609 | F9: 9104 | G9: 18196 | H9: 11086 | I9: 6573 | J9: 5515 | K9: 2241
B10: 대전광역시 | C10: =SUM(D10:K10) -> 131054 | D10: 37558 | E10: 32455 | F10: 10166 | G10: 23443 | H10: 14299 | I10: 5999 | J10: 4648 | K10: 2486
B11: 울산광역시 | C11: =SUM(D11:K11) -> 137107 | D11: 46899 | E11: 32979 | F11: 11565 | G11: 20891 | H11: 12128 | I11: 6709 | J11: 4116 | K11: 1820
B12: 세종특별자치시 | C12: =SUM(D12:K12) -> 35383 | D12: 15199 | E12: 8536 | F12: 2274 | G12: 3257 | H12: 2163 | I12: 1309 | J12: 1972 | K12: 673
B13: 경기도 | C13: =SUM(D13:K13) -> 1265969 | D13: 320040 | E13: 339844 | F13: 121954 | G13: 197091 | H13: 154900 | I13: 64402 | J13: 47331 | K13: 20407
B14: 강원특별자치도 | C14: =SUM(D14:K14) -> 437539 | D14: 240868 | E14: 96440 | F14: 26131 | G14: 33625 | H14: 20697 | I14: 12212 | J14: 5954 | K14: 1612
B15: 충청북도 | C15: =SUM(D15:K15) -> 407286 | D15: 198602 | E15: 97305 | F15: 25865 | G15: 37702 | H15: 24910 | I15: 14102 | J15: 6813 | K15: 1987
B16: 충청남도 | C16: =SUM(D16:K16) -> 564466 | D16: 293708 | E16: 124671 | F16: 32460 | G16: 45560 | H16: 35761 | I16: 20426 | J16: 9089 | K16: 2791
... B21: 제주특별자치도 | C21: =SUM(D21:K21) -> 189336 | D21: 101610 | E21: 41497 | F21: 11493 | G21: 14845 | H21: 11449 | I21: 5832 | J21: 2307 | K21: 303

Sheet 7-3. 소유주체별
A1: 7-3. 2023년 소유주체별 현황
L2: (단위 : 동, ㎡)
B3: 시도 | C3: 합계 | E3: 개인 | G3: 법인 | I3: 국공유 | K3: 기타
C4: 동 수 | D4: 연면적 | E4: 동 수 | F4: 연면적 | G4: 동 수 | H4: 연면적 | I4: 동 수 | J4: 연면적 | K4: 동 수 | L4: 연면적
B5: 전국 | C5: =SUM(E5,G5,I5,K5) -> 7391084 | D5: =SUM(F5,H5,J5,L5) -> 4.2276607e+09 | E5: 5715562.2 | F5: 1.1360891e+09 | G5: 577321.44 | H5: 7.7489342e+08 | I5: 237091.28 | J5: 2.4165513e+08 | K5: 861109.06 | L5: 2.0750231e+09
B6: 서울특별시 | C6: =SUM(E6,G6,I6,K6) -> 579408 | D6: =SUM(F6,H6,J6,L6) -> 5.9422332e+08 | E6: 378995.1 | F6: 1.1511452e+08 | G6: 29681.67 | H6: 84450374 | I6: 12457.37 | J6: 26664572 | K6: 158273.86 | L6: 3.6799385e+08
B7: 부산광역시 | C7: =SUM(E7,G7,I7,K7) -> 348634 | D7: =SUM(F7,H7,J7,L7) -> 2.5584108e+08 | E7: 264820.49 | F7: 49384479 | G7: 27202.25 | H7: 39800926 | I7: 9372.44 | J7: 15527712 | K7: 47238.82 | L7: 1.5112796e+08
B8: 대구광역시 | C8: =SUM(E8,G8,I8,K8) -> 256240.99 | D8: =SUM(F8,H8,J8,L8) -> 1.8144026e+08 | E8: 205100.95 | F8: 50592897 | G8: 17304.2 | H8: 25976751 | I8: 5699.33 | J8: 12168315 | K8: 28136.51 | L8: 92702298
B9: 인천광역시 | C9: =SUM(E9,G9,I9,K9) -> 221783 | D9: =SUM(F9,H9,J9,L9) -> 2.2303799e+08 | E9: 141101.78 | F9: 36222739 | G9: 21436.29 | H9: 40038349 | I9: 8799.92 | J9: 11075485 | K9: 50445.01 | L9: 1.3570142e+08
B10: 광주광역시 | C10: =SUM(E10,G10,I10,K10) -> 136197 | D10: =SUM(F10,H10,J10,L10) -> 1.1011157e+08 | E10: 104790.42 | F10: 23715946 | G10: 12586.37 | H10: 18972205 | I10: 3394.94 | J10: 7508607.9 | K10: 15425.27 | L10: 59914816
B11: 대전광역시 | C11: =SUM(E11,G11,I11,K11) -> 131054 | D11: =SUM(F11,H11,J11,L11) -> 1.1635192e+08 | E11: 100455.35 | F11: 26565310 | G11: 10484.26 | H11: 20124425 | I11: 4519.78 | J11: 7919895.5 | K11: 15594.61 | L11: 61742286
B12: 울산광역시 | C12: =SUM(E12,G12,I12,K12) -> 137107.01 | D12: =SUM(F12,H12,J12,L12) -> 94810829 | E12: 97799.42 | F12: 23051926 | G12: 22920.2 | H12: 26917398 | I12: 3797.56 | J12: 4820378.6 | K12: 12589.83 | L12: 40021127
B13: 세종특별자치시 | C13: =SUM(E13,G13,I13,K13) -> 35383 | D13: =SUM(F13,H13,J13,L13) -> 31939700 | E13: 25551.41 | F13: 4522053.5 | G13: 3215.16 | H13: 4904749.5 | I13: 1790.2 | J13: 3710417.1 | K13: 4826.23 | L13: 18802479
B14: 경기도 | C14: =SUM(E14,G14,I14,K14) -> 1265969 | D14: =SUM(F14,H14,J14,L14) -> 1.1085574e+09 | E14: 884715.86 | F14: 233243261 | G14: 136735.65 | H14: 1.9107377e+08 | I14: 42392.13 | J14: 50128285 | K14: 202125.36 | L14: 6.3411205e+08
B15: 강원특별자치도 | C15: =SUM(E15,G15,I15,K15) -> 437539 | D15: =SUM(F15,H15,J15,L15) -> 1.4583537e+08 | E15: 356052.01 | F15: 54393642 | G15: 25438.03 | H15: 21128570 | I15: 27095.92 | J15: 17642777 | K15: 28953.04 | L15: 52670383
B16: 충청북도 | C16: =SUM(E16,G16,I16,K16) -> 407286.01 | D16: =SUM(F16,H16,J16,L16) -> 1.6200215e+08 | E16: 329122.16 | F16: 58631526 | G16: 35446.25 | H16: 40818539 | I16: 13543.72 | J16: 10739234 | K16: 29173.88 | L16: 51812850
... B22: 제주특별자치도 | C22: =SUM(E22,G22,I22,K22) -> 189336.01 | D22: =SUM(F22,H22,J22,L22) -> 59414426 | E22: 151800.01 | F22: 22771058 | G22: 12469.63 | H22: 9116327.4 | I22: 4756.95 | J22: 3689402.3 | K22: 20309.42 | L22: 23837638

Sheet 8-1. 1인당 건축물 현황(시도별)
A1: 8-1. 2023년 1인당 건축물 현황(시도별)
A2: [기준] 인구수 : 행정안전부 2023년 12월 주민등록 인구 및 세대현황 참조(https://jumin.mois.go.kr)
O3: (단위 : ㎡)
B4: 시도 | C4: 인구수 | D4: 합계 | F4: 주거용 | H4: 상업용 | J4: 공업용 | L4: 교육 및 사회용 | N4: 기타
D5: 연면적 | E5: 1인당 면적 | F5: 연면적 | G5: 1인당 면적 | H5: 연면적 | I5: 1인당 면적 | J5: 연면적 | K5: 1인당 면적 | L5: 연면적 | M5: 1인당 면적 | N5: 연면적 | O5: 1인당 면적
B6: 합계 | C6: 51325329 | D6: ='1. 용도별'!D5 -> 4.2276607e+09 | E6: =D6/$C6 -> 82.36987 | F6: ='1. 용도별'!F5 -> 1.9505563e+09 | G6: =F6/$C6 -> 38.003775 | H6: ='1. 용도별'!H5 -> 9.3468869e+08 | I6: =H6/$C6 -> 18.211061 | J6: ='1. 용도별'!J5 -> 4.6514802e+08 | K6: =J6/$C6 -> 9.0627382 | L6: ='1. 용도별'!L5 -> 3.7664541e+08 | M6: =L6/$C6 -> 7.3383925 | N6: ='1. 용도별'!N5 -> 5.0062229e+08 | O6: =N6/$C6 -> 9.7539033
B7: 서울특별시 | C7: 9386034 | D7: ='1. 용도별'!D6 -> 5.9422332e+08 | E7: =D7/$C7 -> 63.309308 | F7: ='1. 용도별'!F6 -> 3.0847809e+08 | G7: =F7/$C7 -> 32.865648 | H7: ='1. 용도별'!H6 -> 1.8678264e+08 | I7: =H7/$C7 -> 19.90006 | J7: ='1. 용도별'!J6 -> 14552067 | K7: =J7/$C7 -> 1.5503957 | L7: ='1. 용도별'!L6 -> 63430315 | M7: =L7/$C7 -> 6.7579464 | N7: ='1. 용도별'!N6 -> 20980204 | O7: =N7/$C7 -> 2.2352576
B8: 부산광역시 | C8: 3293362 | D8: ='1. 용도별'!D7 -> 2.5584108e+08 | E8: =D8/$C8 -> 77.683862 | F8: ='1. 용도별'!F7 -> 1.2462408e+08 | G8: =F8/$C8 -> 37.840991 | H8: ='1. 용도별'!H7 -> 64595346 | I8: =H8/$C8 -> 19.613801 | J8: ='1. 용도별'!J7 -> 19867250 | K8: =J8/$C8 -> 6.0325134 | L8: ='1. 용도별'!L7 -> 23981385 | M8: =L8/$C8 -> 7.2817338 | N8: ='1. 용도별'!N7 -> 22773015 | O8: =N8/$C8 -> 6.9148231
B9: 대구광역시 | C9: 2374960 | D9: ='1. 용도별'!D8 -> 1.8144026e+08 | E9: =D9/$C9 -> 76.397186 | F9: ='1. 용도별'!F8 -> 95283309 | G9: =F9/$C9 -> 40.119964 | H9: ='1. 용도별'!H8 -> 45453596 | I9: =H9/$C9 -> 19.138678 | J9: ='1. 용도별'!J8 -> 16290192 | K9: =J9/$C9 -> 6.8591439 | L9: ='1. 용도별'!L8 -> 16051156 | M9: =L9/$C9 -> 6.7584954 | N9: ='1. 용도별'!N8 -> 8362007.8 | O9: =N9/$C9 -> 3.5209047
B10: 인천광역시 | C10: 2997410 | D10: ='1. 용도별'!D9 -> 2.2303799e+08 | E10: =D10/$C10 -> 74.410238 | F10: ='1. 용도별'!F9 -> 1.0741546e+08 | G10: =F10/$C10 -> 35.836092 | H10: ='1. 용도별'!H9 -> 55915629 | I10: =H10/$C10 -> 18.654648 | J10: ='1. 용도별'!J9 -> 25115386 | K10: =J10/$C10 -> 8.3790291 | L10: ='1. 용도별'!L9 -> 18087502 | M10: =L10/$C10 -> 6.0343769 | N10: ='1. 용도별'!N9 -> 16504017 | O10: =N10/$C10 -> 5.5060924
B11: 광주광역시 | C11: 1419237 | D11: ='1. 용도별'!D10 -> 1.1011157e+08 | E11: =D11/$C11 -> 77.585051 | F11: ='1. 용도별'!F10 -> 59857078 | G11: =F11/$C11 -> 42.175534 | H11: ='1. 용도별'!H10 -> 24411788 | I11: =H11/$C11 -> 17.200642 | J11: ='1. 용도별'!J10 -> 8781783.8 | K11: =J11/$C11 -> 6.1876796 | L11: ='1. 용도별'!L10 -> 12869132 | M11: =L11/$C11 -> 9.067641 | N11: ='1. 용도별'!N10 -> 4191793.4 | O11: =N11/$C11 -> 2.9535542
B12: 대전광역시 | C12: 1442216 | D12: ='1. 용도별'!D11 -> 1.1635192e+08 | E12: =D12/$C12 -> 80.675791 | F12: ='1. 용도별'!F11 -> 57280772 | G12: =F12/$C12 -> 39.717194 | H12: ='1. 용도별'!H11 -> 25161964 | I12: =H12/$C12 -> 17.446738 | J12: ='1. 용도별'!J11 -> 5662874.7 | K12: =J12/$C12 -> 3.9265094 | L12: ='1. 용도별'!L11 -> 15094653 | M12: =L12/$C12 -> 10.466291 | N12: ='1. 용도별'!N11 -> 13151653 | O12: =N12/$C12 -> 9.119059
B13: 울산광역시 | C13: 1103661 | D13: ='1. 용도별'!D12 -> 94810829 | E13: =D13/$C13 -> 85.905753 | F13: ='1. 용도별'!F12 -> 44358548 | G13: =F13/$C13 -> 40.192186 | H13: ='1. 용도별'!H12 -> 18547143 | I13: =H13/$C13 -> 16.805108 | J13: ='1. 용도별'!J12 -> 18653920 | K13: =J13/$C13 -> 16.901857 | L13: ='1. 용도별'!L12 -> 7335576.7 | M13: =L13/$C13 -> 6.6465851 | N13: ='1. 용도별'!N12 -> 5915641.6 | O13: =N13/$C13 -> 5.3600169
B14: 세종특별자치시 | C14: 386525 | D14: ='1. 용도별'!D13 -> 31939700 | E14: =D14/$C14 -> 82.632946 | F14: ='1. 용도별'!F13 -> 16035868 | G14: =F14/$C14 -> 41.487272 | H14: ='1. 용도별'!H13 -> 5875166.6 | I14: =H14/$C14 -> 15.199965 | J14: ='1. 용도별'!J13 -> 2982271.5 | K14: =J14/$C14 -> 7.715598 | L14: ='1. 용도별'!L13 -> 3300221.3 | M14: =L14/$C14 -> 8.5381833 | N14: ='1. 용도별'!N13 -> 3746172.5 | O14: =N14/$C14 -> 9.691928
B15: 경기도 | C15: 13630821 | D15: ='1. 용도별'!D14 -> 1.1085574e+09 | E15: =D15/$C15 -> 81.327264 | F15: ='1. 용도별'!F14 -> 5.0265909e+08 | G15: =F15/$C15 -> 36.876656 | H15: ='1. 용도별'!H14 -> 2.2877838e+08 | I15: =H15/$C15 -> 16.783904 | J15: ='1. 용도별'!J14 -> 1.3591984e+08 | K15: =J15/$C15 -> 9.9715082 | L15: ='1. 용도별'!L14 -> 84771583 | M15: =L15/$C15 -> 6.2191106 | N15: ='1. 용도별'!N14 -> 1.5642847e+08 | O15: =N15/$C15 -> 11.476086
B16: 강원특별자치도 | C16: 1527807 | D16: ='1. 용도별'!D15 -> 1.4583537e+08 | E16: =D16/$C16 -> 95.454053 | F16: ='1. 용도별'!F15 -> 64847506 | G16: =F16/$C16 -> 42.444828 | H16: ='1. 용도별'!H15 -> 33239229 | I16: =H16/$C16 -> 21.75617 | J16: ='1. 용도별'!J15 -> 7464148.8 | K16: =J16/$C16 -> 4.8855312 | L16: ='1. 용도별'!L15 -> 17151380 | M16: =L16/$C16 -> 11.226143 | N16: ='1. 용도별'!N15 -> 23133107 | O16: =N16/$C16 -> 15.14138
B17: 충청북도 | C17: 1593469 | D17: ='1. 용도별'!D16 -> 1.6200215e+08 | E17: =D17/$C17 -> 101.66633 | F17: ='1. 용도별'!F16 -> 68352953 | G17: =F17/$C17 -> 42.89569 | H17: ='1. 용도별'!H16 -> 27674039 | I17: =H17/$C17 -> 17.367165 | J17: ='1. 용도별'!J16 -> 29701761 | K17: =J17/$C17 -> 18.639685 | L17: ='1. 용도별'!L16 -> 13844344 | M17: =L17/$C17 -> 8.6881793 | N17: ='1. 용도별'!N16 -> 22429053 | O17: =N17/$C17 -> 14.075613
... B23: 제주특별자치도 | C23: 675252 | D23: ='1. 용도별'!D22 -> 59414426 | E23: =D23/$C23 -> 87.988523 | F23: ='1. 용도별'!F22 -> 25424250 | G23: =F23/$C23 -> 37.651499 | H23: ='1. 용도별'!H22 -> 19920379 | I23: =H23/$C23 -> 29.500659 | J23: ='1. 용도별'!J22 -> 849633.85 | K23: =J23/$C23 -> 1.2582471 | L23: ='1. 용도별'!L22 -> 5540625.6 | M23: =L23/$C23 -> 8.2052709 | N23: ='1. 용도별'!N22 -> 7679537.4 | O23: =N23/$C23 -> 11.372847

Sheet 8-2. 1인당 건축물 현황(시군구별)
A1: 8-2. 2023년 1인당 건축물 현황(시군구별)
A2: [기준] 인구수 : 행정안전부 2023년 12월 주민등록 인구 및 세대현황 참조(https://jumin.mois.go.kr)
B4: 시도 | C4: 시군구 | D4: 인구 | E4: 전체 건축물 | G4: 주거용 건축물
E5: 건축물 연면적 | F5: 1인당 면적 | G5: 주거용 연면적 | H5: 1인당 면적
B6: 서울 | C6: 종로구 | D6: 139417 | E6: ='5-2. 30년이상 건축물(시군구별) '!D6 -> 19667796 | F6: =E6/$D$6 -> 141.07172 | G6: ='5-2. 30년이상 건축물(시군구별) '!G6 -> 5067119.8 | H6: =G6/$D$6 -> 36.345064
B7: 서울 | C7: 중구 | D7: 121312 | E7: ='5-2. 30년이상 건축물(시군구별) '!D7 -> 22465284 | F7: =E7/$D$6 -> 161.13734 | G7: ='5-2. 30년이상 건축물(시군구별) '!G7 -> 4577012 | H7: =G7/$D$6 -> 32.829655
B8: 서울 | C8: 용산구 | D8: 213151 | E8: ='5-2. 30년이상 건축물(시군구별) '!D8 -> 17734347 | F8: =E8/$D$6 -> 127.20362 | G8: ='5-2. 30년이상 건축물(시군구별) '!G8 -> 8877857.2 | H8: =G8/$D$6 -> 63.678441
B9: 서울 | C9: 성동구 | D9: 277361 | E9: ='5-2. 30년이상 건축물(시군구별) '!D9 -> 19934802 | F9: =E9/$D$6 -> 142.98688 | G9: ='5-2. 30년이상 건축물(시군구별) '!G9 -> 9364345.5 | H9: =G9/$D$6 -> 67.167888
B10: 서울 | C10: 광진구 | D10: 335554 | E10: ='5-2. 30년이상 건축물(시군구별) '!D10 -> 17097833 | F10: =E10/$D$6 -> 122.63808 | G10: ='5-2. 30년이상 건축물(시군구별) '!G10 -> 9971910.5 | H10: =G10/$D$6 -> 71.525786
B11: 서울 | C11: 동대문구 | D11: 341149 | E11: ='5-2. 30년이상 건축물(시군구별) '!D11 -> 19004726 | F11: =E11/$D$6 -> 136.3157 | G11: ='5-2. 30년이상 건축물(시군구별) '!G11 -> 10433954 | H11: =G11/$D$6 -> 74.839901
B12: 서울 | C12: 중랑구 | D12: 382155 | E12: ='5-2. 30년이상 건축물(시군구별) '!D12 -> 22167195 | F12: =E12/$D$6 -> 158.99922 | G12: ='5-2. 30년이상 건축물(시군구별) '!G12 -> 14191795 | H12: =G12/$D$6 -> 101.79386
B13: 서울 | C13: 성북구 | D13: 425602 | E13: ='5-2. 30년이상 건축물(시군구별) '!D13 -> 21591756 | F13: =E13/$D$6 -> 154.87176 | G13: ='5-2. 30년이상 건축물(시군구별) '!G13 -> 14285216 | H13: =G13/$D$6 -> 102.46394
B14: 서울 | C14: 강북구 | D14: 288113 | E14: ='5-2. 30년이상 건축물(시군구별) '!D14 -> 12826476 | F14: =E14/$D$6 -> 92.000803 | G14: ='5-2. 30년이상 건축물(시군구별) '!G14 -> 8561701.1 | H14: =G14/$D$6 -> 61.41074
B15: 서울 | C15: 도봉구 | D15: 306948 | E15: ='5-2. 30년이상 건축물(시군구별) '!D15 -> 15932860 | F15: =E15/$D$6 -> 114.28204 | G15: ='5-2. 30년이상 건축물(시군구별) '!G15 -> 10149854 | H15: =G15/$D$6 -> 72.802125
B16: 서울 | C16: 노원구 | D16: 498213 | E16: ='5-2. 30년이상 건축물(시군구별) '!D16 -> 22673444 | F16: =E16/$D$6 -> 162.63041 | G16: ='5-2. 30년이상 건축물(시군구별) '!G16 -> 15807225 | H16: =G16/$D$6 -> 113.3809
B17: 서울 | C17: 은평구 | D17: 466770 | E17: ='5-2. 30년이상 건축물(시군구별) '!D17 -> 20812060 | F17: =E17/$D$6 -> 149.27921 | G17: ='5-2. 30년이상 건축물(시군구별) '!G17 -> 14383417 | H17: =G17/$D$6 -> 103.16831
... B80: 울산 | C80: 울주군 | D80: 218997 | E80: ='5-2. 30년이상 건축물(시군구별) '!D80 -> 23758512 | F80: =E80/$D$6 -> 170.41331 | G80: ='5-2. 30년이상 건축물(시군구별) '!G80 -> 8761591.6 | H80: =G80/$D$6 -> 62.844499
B81: 세종 | D81: 386525 | E81: ='5-2. 30년이상 건축물(시군구별) '!D81 -> 31939700 | F81: =E81/$D$6 -> 229.09473 | G81: ='5-2. 30년이상 건축물(시군구별) '!G81 -> 16035868 | H81: =G81/$D$6 -> 115.02089
B82: 경기 | C82: 수원시 장안구 | D82: 270849 | E82: ='5-2. 30년이상 건축물(시군구별) '!D82 -> 14351073 | F82: =E82/$D$6 -> 102.93632 | G82: ='5-2. 30년이상 건축물(시군구별) '!G82 -> 9234494.4 | H82: =G82/$D$6 -> 66.236502
B83: 경기 | C83: 수원시 권선구 | D83: 366167 | E83: ='5-2. 30년이상 건축물(시군구별) '!D83 -> 22456259 | F83: =E83/$D$6 -> 161.0726 | G83: ='5-2. 30년이상 건축물(시군구별) '!G83 -> 13029104 | H83: =G83/$D$6 -> 93.454198
B84: 경기 | C84: 수원시 팔달구 | D84: 197213 | E84: ='5-2. 30년이상 건축물(시군구별) '!D84 -> 13606402 | F84: =E84/$D$6 -> 97.595002 | G84: ='5-2. 30년이상 건축물(시군구별) '!G84 -> 6549463.1 | H84: =G84/$D$6 -> 46.977507
B85: 경기 | C85: 수원시 영통구 | D85: 363028 | E85: ='5-2. 30년이상 건축물(시군구별) '!D85 -> 28283351 | F85: =E85/$D$6 -> 202.86874 | G85: ='5-2. 30년이상 건축물(시군구별) '!G85 -> 12763090 | H85: =G85/$D$6 -> 91.546153
B86: 경기 | C86: 성남시 수정구 | D86: 235942 | E86: ='5-2. 30년이상 건축물(시군구별) '!D86 -> 13922632 | F86: =E86/$D$6 -> 99.863229 | G86: ='5-2. 30년이상 건축물(시군구별) '!G86 -> 6734816.9 | H86: =G86/$D$6 -> 48.306999
B87: 경기 | C87: 성남시 중원구 | D87: 210848 | E87: ='5-2. 30년이상 건축물(시군구별) '!D87 -> 12755613 | F87: =E87/$D$6 -> 91.492526 | G87: ='5-2. 30년이상 건축물(시군구별) '!G87 -> 6133313.7 | H87: =G87/$D$6 -> 43.992581
B88: 경기 | C88: 성남시 분당구 | D88: 472957 | E88: ='5-2. 30년이상 건축물(시군구별) '!D88 -> 63820015 | F88: =E88/$D$6 -> 457.76351 | G88: ='5-2. 30년이상 건축물(시군구별) '!G88 -> 22543218 | H88: =G88/$D$6 -> 161.69633
B89: 경기 | C89: 의정부시 | D89: 464213 | E89: ='5-2. 30년이상 건축물(시군구별) '!D89 -> 25549268 | F89: =E89/$D$6 -> 183.25791 | G89: ='5-2. 30년이상 건축물(시군구별) '!G89 -> 15412294 | H89: =G89/$D$6 -> 110.54817
B90: 경기 | C90: 안양시 만안구 | D90: 230664 | E90: ='5-2. 30년이상 건축물(시군구별) '!D90 -> 13449042 | F90: =E90/$D$6 -> 96.466302 | G90: ='5-2. 30년이상 건축물(시군구별) '!G90 -> 7032184.8 | H90: =G90/$D$6 -> 50.439938
B91: 경기 | C91: 안양시 동안구 | D91: 313996 | E91: ='5-2. 30년이상 건축물(시군구별) '!D91 -> 21644106 | F91: =E91/$D$6 -> 155.24725 | G91: ='5-2. 30년이상 건축물(시군구별) '!G91 -> 10242240 | H91: =G91/$D$6 -> 73.464786
B92: 경기 | C92: 부천시 | D92: 779968 | E92: ='5-2. 30년이상 건축물(시군구별) '!D92 -> 54335959 | F92: =E92/$D$6 -> 389.73697 | G92: ='5-2. 30년이상 건축물(시군구별) '!G92 -> 25536864 | H92: =G92/$D$6 -> 183.16894
B93: 경기 | C93: 광명시 | D93: 280197 | E93: ='5-2. 30년이상 건축물(시군구별) '!D93 -> 16273159 | F93: =E93/$D$6 -> 116.72292 | G93: ='5-2. 30년이상 건축물(시군구별) '!G93 -> 9038913.5 | H93: =G93/$D$6 -> 64.833654
... B255: 제주 | C255: 서귀포시 | D255: 183598 | E255: ='5-2. 30년이상 건축물(시군구별) '!D255 -> 20391188 | F255: =E255/$D$6 -> 146.26041 | G255: ='5-2. 30년이상 건축물(시군구별) '!G255 -> 7470531.6 | H255: =G255/$D$6 -> 53.584079

Sheet 9. 국토면적 대비 건축물 현황
A1: =목차!B12 -> 9. 2023년 국토면적 대비 건축물 현황
A2: [기준] 국토면적 : 국가통계포털 행정구역별・지목별 국토이용현황(2022년 기준) 참고(https://kosis.kr/)
O3: (단위 : ㎡)
B4: 시도 | C4: 지적공부면적지 | D4: 합계 | F4: 주거용 | H4: 상업용 | J4: 공업용 | L4: 교육 및 사회용 | N4: 기타
D5: 연면적 | E5: 비율 | F5: 연면적 | G5: 비율 | H5: 연면적 | I5: 비율 | J5: 연면적 | K5: 비율 | L5: 연면적 | M5: 비율 | N5: 연면적 | O5: 비율
B6: 합계 | C6: 1.0044355e+11 | D6: ='1. 용도별'!D5 -> 4.2276607e+09 | E6: =D6/$C6*100 -> 4.2089916 | F6: ='1. 용도별'!F5 -> 1.9505563e+09 | G6: =F6/$C6*100 -> 1.9419427 | H6: ='1. 용도별'!H5 -> 9.3468869e+08 | I6: =H6/$C6*100 -> 0.93056115 | J6: ='1. 용도별'!J5 -> 4.6514802e+08 | K6: =J6/$C6*100 -> 0.46309395 | L6: ='1. 용도별'!L5 -> 3.7664541e+08 | M6: =L6/$C6*100 -> 0.37498216 | N6: ='1. 용도별'!N5 -> 5.0062229e+08 | O6: =N6/$C6*100 -> 0.49841157
